Workbook

Sheet FC 합계
A1: 2025. 12월 FC 커미션 예측 현황
A3: 성명 | D3: 사번
A5: 구분 | B5: 보험사 | C5: 모집업적 | D5: 환산업적 | E5: 1차년 | H5: 2차년 | O5: 3차년 | Q5: 4차년 | V5: 합계 | W5: 비고
E6: 익월 | F6: 2~12회 분급 | G6: 7~12회 분급 | H6: 13회차 | I6: 13~14회차 분급 | J6: 13~15회차 분급 | K6: 13~16회차 분급 | L6: 13~24회차 분급 | M6: 14~24회차 분급 | N6: 25~35회차 분급 | O6: 25~36회차 분급 | P6: 36회차 | Q6: 37회 | R6: 37~42회차 분급 | S6: 37~48회차 분급 | T6: 38~120회차 분급 | U6: 37~240회차 분급
A7: 생명보험 | B7: KB라이프 | C7: =KB라이프!AK6 -> 0 | D7: =KB라이프!AL6 -> 0 | E7: =KB라이프!AM6 -> 0 | F7: =+KB라이프!AN6 -> 0 | H7: =+KB라이프!AO6 -> 0 | O7: =+KB라이프!BC6 -> 0 | S7: =+KB라이프!BP6 -> 0 | V7: =SUM(E7:U7) -> 0
B8: 미래에셋 | C8: =+미래에셋!DV6 -> 0 | D8: =+미래에셋!DW6 -> 0 | E8: =+미래에셋!DX6 -> 0 | G8: =+미래에셋!EE6 -> 0 | L8: =+미래에셋!ER6 -> 0 | O8: =+미래에셋!FE6 -> 0 | Q8: =+미래에셋!FF6 -> 0 | T8: =미래에셋!IL6 -> 0 | V8: =SUM(E8:U8) -> 0
B9: 삼성생명 | C9: =+삼성생명!AO6 -> 0 | D9: =+삼성생명!AP6 -> 0 | E9: =+삼성생명!AQ6 -> 0 | G9: =+삼성생명!AX6 -> 0 | L9: =+삼성생명!BK6 -> 0 | O9: =+삼성생명!BX6 -> 0 | U9: =+삼성생명!BY6 -> 0 | V9: =SUM(E9:U9) -> 0
B10: IM라이프 | C10: =+IM라이프!BF7 -> 0 | D10: =+IM라이프!BG7 -> 0 | E10: =+IM라이프!BH7 -> 0 | F10: =+IM라이프!BT7 -> 0 | L10: =+IM라이프!CG7 -> 0 | O10: =+IM라이프!CT7 -> 0 | S10: =+IM라이프!DG7 -> 0 | V10: =SUM(E10:U10) -> 0
B11: 교보생명 | C11: =+교보생명!AP6 -> 0 | D11: =+교보생명!AQ6 -> 0 | E11: =+교보생명!AR6 -> 0 | G11: =+교보생명!AY6 -> 0 | L11: =+교보생명!BL6 -> 0 | O11: =+교보생명!BY6 -> 0 | V11: =SUM(E11:U11) -> 0
B12: 한화생명(신규) | C12: =+한화생명!BC7 -> 0 | D12: =+한화생명!BD7 -> 0 | E12: =+한화생명!BE7 -> 0 | F12: =+한화생명!BQ7 -> 0 | H12: =+한화생명!BR7 -> 0 | M12: =+한화생명!CD7 -> 0 | N12: =+한화생명!CP7 -> 0 | P12: =+한화생명!CQ7 -> 0 | R12: =+한화생명!CX7 -> 0 | V12: =SUM(E12:U12) -> 0
A13: 생명보험 소계 | C13: =SUM(C7:C12) -> 0 | D13: =SUM(D7:D12) -> 0 | E13: =SUM(E7:E12) -> 0 | F13: =SUM(F7:F12) -> 0 | G13: =SUM(G7:G12) -> 0 | H13: =SUM(H7:H12) -> 0 | I13: =SUM(I7:I12) -> 0 | J13: =SUM(J7:J12) -> 0 | ... V13: =SUM(V7:V12) -> 0
A14: 손해보험 | B14: KB손해보험 | C14: =+KB손해보험!T6 -> 0 | D14: =+KB손해보험!U6 -> 0 | E14: =+KB손해보험!V6 -> 0 | G14: =+KB손해보험!AC6 -> 0 | J14: =+KB손해보험!AG6 -> 0 | V14: =SUM(E14:U14) -> 0
B15: 현대해상 | C15: =+현대해상!T6 -> 0 | D15: =+현대해상!U6 -> 0 | E15: =+현대해상!V6 -> 0 | G15: =+현대해상!AC6 -> 0 | J15: =+현대해상!AG6 -> 0 | V15: =SUM(E15:U15) -> 0
B16: 메리츠화재 | C16: =+메리츠화재!R6 -> 0 | D16: =+메리츠화재!S6 -> 0 | E16: =+메리츠화재!T6 -> 0 | G16: =+메리츠화재!AA6 -> 0 | I16: =+메리츠화재!AD6 -> 0 | V16: =SUM(E16:U16) -> 0
B17: DB손해보험 | C17: =+DB손해보험!T6 -> 0 | D17: =+DB손해보험!U6 -> 0 | E17: =+DB손해보험!V6 -> 0 | G17: =+DB손해보험!AC6 -> 0 | J17: =+DB손해보험!AG6 -> 0 | V17: =SUM(E17:U17) -> 0
B18: 한화손해보험 | C18: =+한화손해보험!V6 -> 0 | D18: =+한화손해보험!W6 -> 0 | E18: =+한화손해보험!X6 -> 0 | F18: =+한화손해보험!AJ6 -> 0 | I18: =+한화손해보험!AM6 -> 0 | V18: =SUM(E18:U18) -> 0
B19: 삼성화재 | C19: =+삼성화재!U6 -> 0 | D19: =+삼성화재!V6 -> 0 | E19: =+삼성화재!W6 -> 0 | G19: =+삼성화재!AD6 -> 0 | J19: =+삼성화재!AH6 -> 0 | V19: =SUM(E19:U19) -> 0
B20: 라이나손보 | C20: =+라이나손보!Z6 -> 0 | D20: =+라이나손보!AA6 -> 0 | E20: =+라이나손보!AB6 -> 0 | F20: =+라이나손보!AN6 -> 0 | K20: =+라이나손보!AR6 -> 0 | V20: =SUM(E20:U20) -> 0
A21: 손해보험 소계 | C21: =SUM(C14:C20) -> 0 | D21: =SUM(D14:D20) -> 0 | E21: =SUM(E14:E20) -> 0 | F21: =SUM(F14:F20) -> 0 | G21: =SUM(G14:G20) -> 0 | H21: =SUM(H14:H20) -> 0 | I21: =SUM(I14:I20) -> 0 | J21: =SUM(J14:J20) -> 0 | ... M21: =SUM(M14:M20) -> 0 | O21: =SUM(O14:O20) -> 0 | Q21: =SUM(Q14:Q20) -> 0 | S21: =SUM(S14:S20) -> 0 | U21: =SUM(U14:U20) -> 0 | V21: =SUM(E21:U21) -> 0
A22: 총계 | C22: =SUM(C21,C13) -> 0 | D22: =SUM(D21,D13) -> 0 | E22: =SUM(E21,E13) -> 0 | F22: =SUM(F21,F13) -> 0 | G22: =SUM(G21,G13) -> 0 | H22: =SUM(H21,H13) -> 0 | I22: =SUM(I21,I13) -> 0 | J22: =SUM(J21,J13) -> 0 | ... M22: =SUM(M21,M13) -> 0 | O22: =SUM(O21,O13) -> 0 | Q22: =SUM(Q21,Q13) -> 0 | S22: =SUM(S21,S13) -> 0 | U22: =SUM(U21,U13) -> 0 | V22: =SUM(E22:U22) -> 0
A24: ※ 유의사항 1. 본 양식은 내부 단순 참고용 자료이므로, 외부 유출을 절대 금합니다. 2. 산출된 금액은 세전 금액이며, 주계약을 기준으로 산출된 내용이므로 실지급액과 차이가 있을 수 있습니다. 3. 산출된 금액은 영업에 대한 커미션에 대해서만 산출되었으며, 시책의 경우 별도 산출 및 합산 필요합니다.

Sheet KB라이프
A1: [KB라이프] "상품별 MIP 比 지급률 예시"
A2: 1. 주계약의 보험료 기준 예시이며, 특약 부가 시 지급률 변동될 수 있음 | AK2: f
A3: 2. 회사 전체 업적 달성 구간, 실제 산출 대상 보험료 및 특약별 지급률, 제휴사 수수료 정책 등에 따라 변동될 수 있음
A4: 3. 보수 지급액 = 월납화 초회 보험료 x 지급률*(지급률 예시 참조)
A5: ※ 제휴사 전개 프로모션/시상은 본 예시에서 제외
AK6: =SUBTOTAL(9,AK12:AK162) -> 0 | AL6: =SUBTOTAL(9,AL12:AL162) -> 0 | AM6: =SUBTOTAL(9,AM12:AM162) -> 0 | AN6: =SUBTOTAL(9,AN12:AN162) -> 0 | AO6: =SUBTOTAL(9,AO12:AO162) -> 0 | AP6: =SUBTOTAL(9,AP12:AP162) -> 0 | AQ6: =SUBTOTAL(9,AQ12:AQ162) -> 0 | AR6: =SUBTOTAL(9,AR12:AR162) -> 0 | ... BQ6: =SUBTOTAL(9,BQ12:BQ162) -> 0
A7: 상품명 | B7: 납입기간 | C7: 가입금액 | D7: 특약구분 | E7: 환산율 | F7: 2025년 FC 수수료 | AM7: 수당확인 | BW7: 총량
F8: 0.6 | AK8: 모집업적 | AL8: 환산업적 | BW8: 월납화 보험료 x 하기 지급률
F9: 초년도 | H9: 2차년도 | V9: 3차년도 | AI9: 4차년도 | AJ9: FC계 | AK9: (월초P) | AM9: 초년도 | AO9: 2차년도 | BC9: 3차년도 | BP9: 4차년도 | BQ9: FC계 | BW9: 초년도 | BY9: 2차년도 | CA9: 3차년도 | CB9: 4차년도 | CC9: Total
F10: 익월 | G10: 2~12회차 | H10: 13회차 | I10: 14~24회차 | J10: 25회차 | K10: 26회 | L10: 27회 | M10: 28회 | N10: 29회 | O10: 30회 | P10: 31회 | Q10: 32회 | R10: 33회 | S10: 34회 | T10: 35회 | U10: 36회 | V10: 25~36회차 | W10: 37회 | X10: 38회 | Y10: 39회 | Z10: 40회 | AA10: 41회 | AB10: 42회 | AC10: 43회 | AD10: 44회 | AE10: 45회 | AF10: 46회 | AG10: 47회 | AH10: 48회 | AI10: 37~48회차 | AM10: 익월 | AN10: 2~12회차 | AO10: 13회차 | AP10: 14~24회차 | AQ10: 25회 | AR10: 26회 | AS10: 27회 | AT10: 28회 | AU10: 29회 | AV10: 30회 | AW10: 31회 | AX10: 32회 | AY10: 33회 | AZ10: 34회 | BA10: 35회 | BB10: 36회 | BC10: 25~36회차 | BD10: 37회 | BE10: 38회 | BF10: 39회 | BG10: 40회 | BH10: 41회 | BI10: 42회 | BJ10: 43회 | BK10: 44회 | BL10: 45회 | BM10: 46회 | BN10: 47회 | BO10: 48회 | BP10: 37~48회차 | BW10: 익월 | BX10: 2~12회차 | BY10: 13회차 | BZ10: 14~24회차 | CA10: 25~36회차 분급 | CB10: 37~48회차 분급
A12: KB 7년의약속 플러스 평생종신보험 무배당 (해약환급금 일부 지급형)(일반/간편심사형) | B12: 20년납 | C12: - | E12: =CC12/1200% -> 1.011225 | F12: =BW12*$F$8 -> 4.69674 | G12: =BX12*$F$8 -> 0 | H12: =BY12*$F$8 -> 1.81584 | I12: =BZ12*$F$8 -> 0 | J12: =+V12/12 -> 0.06402 | K12: =+J12 -> 0.06402 | L12: =+K12 -> 0.06402 | M12: =+L12 -> 0.06402 | N12: =+M12 -> 0.06402 | O12: =+N12 -> 0.06402 | P12: =+O12 -> 0.06402 | Q12: =+P12 -> 0.06402 | R12: =+Q12 -> 0.06402 | ... U12: =+T12 -> 0.06402 | V12: =CA12*$F$8 -> 0.76824 | W12: =+AI12/12 -> 0 | X12: =+W12 -> 0 | Y12: =+X12 -> 0 | Z12: =+Y12 -> 0 | AA12: =+Z12 -> 0 | AB12: =+AA12 -> 0 | AC12: =+AB12 -> 0 | AD12: =+AC12 -> 0 | AE12: =+AD12 -> 0 | ... AH12: =+AG12 -> 0 | AI12: =CB12*$F$8 -> 0 | AJ12: =CC12*$F$8 -> 7.28082 | AL12: =+ROUNDDOWN($AK12*E12,-1) -> 0 | AM12: =+ROUNDDOWN($AK12*F12,-1) -> 0 | AN12: =+ROUNDDOWN($AK12*G12,-1) -> 0 | AO12: =+ROUNDDOWN($AK12*H12,-1) -> 0 | AP12: =+ROUNDDOWN($AK12*I12,-1) -> 0 | AQ12: =+ROUNDDOWN($AK12*J12,-1) -> 0 | AR12: =+ROUNDDOWN($AK12*K12,-1) -> 0 | AS12: =+ROUNDDOWN($AK12*L12,-1) -> 0 | ... BP12: =+ROUNDDOWN($AK12*AI12,-1) -> 0 | BQ12: =SUM(AM12,AO12,BC12,BP12) -> 0 | BW12: 7.8279 | BX12: 0 | BY12: 3.0264 | BZ12: 0 | CA12: 1.2804 | CB12: 0 | CC12: 12.1347
A13: KB 약속플러스종신보험(해약환급금 일부지급형) | B13: 5년납 | C13: - | E13: =CC13/1200% -> 0.404975 | F13: =BW13*$F$8 -> 1.76346 | G13: =BX13*$F$8 -> 0 | H13: =BY13*$F$8 -> 0.62856 | I13: =BZ13*$F$8 -> 0 | J13: =+V13/12 -> 0.04365 | K13: =+J13 -> 0.04365 | L13: =+K13 -> 0.04365 | M13: =+L13 -> 0.04365 | N13: =+M13 -> 0.04365 | O13: =+N13 -> 0.04365 | P13: =+O13 -> 0.04365 | Q13: =+P13 -> 0.04365 | R13: =+Q13 -> 0.04365 | ... U13: =+T13 -> 0.04365 | V13: =CA13*$F$8 -> 0.5238 | W13: =+AI13/12 -> 0 | X13: =+W13 -> 0 | Y13: =+X13 -> 0 | Z13: =+Y13 -> 0 | AA13: =+Z13 -> 0 | AB13: =+AA13 -> 0 | AC13: =+AB13 -> 0 | AD13: =+AC13 -> 0 | AE13: =+AD13 -> 0 | ... AH13: =+AG13 -> 0 | AI13: =CB13*$F$8 -> 0 | AJ13: =CC13*$F$8 -> 2.91582 | AL13: =+ROUNDDOWN($AK13*E13,-1) -> 0 | AM13: =+ROUNDDOWN($AK13*F13,-1) -> 0 | AN13: =+ROUNDDOWN($AK13*G13,-1) -> 0 | AO13: =+ROUNDDOWN($AK13*H13,-1) -> 0 | AP13: =+ROUNDDOWN($AK13*I13,-1) -> 0 | AQ13: =+ROUNDDOWN($AK13*J13,-1) -> 0 | AR13: =+ROUNDDOWN($AK13*K13,-1) -> 0 | AS13: =+ROUNDDOWN($AK13*L13,-1) -> 0 | ... BP13: =+ROUNDDOWN($AK13*AI13,-1) -> 0 | BQ13: =SUM(AM13,AO13,BC13,BP13) -> 0 | BW13: 2.9391 | BX13: 0 | BY13: 1.0476 | BZ13: 0 | CA13: 0.873 | CB13: 0 | CC13: 4.8597
B14: 7년납 | C14: - | E14: =CC14/1200% -> 0.56745 | F14: =BW14*$F$8 -> 2.04282 | G14: =BX14*$F$8 -> 0 | H14: =BY14*$F$8 -> 1.16982 | I14: =BZ14*$F$8 -> 0 | J14: =+V14/12 -> 0.07275 | K14: =+J14 -> 0.07275 | L14: =+K14 -> 0.07275 | M14: =+L14 -> 0.07275 | N14: =+M14 -> 0.07275 | O14: =+N14 -> 0.07275 | P14: =+O14 -> 0.07275 | Q14: =+P14 -> 0.07275 | R14: =+Q14 -> 0.07275 | ... U14: =+T14 -> 0.07275 | V14: =CA14*$F$8 -> 0.873 | W14: =+AI14/12 -> 0 | X14: =+W14 -> 0 | Y14: =+X14 -> 0 | Z14: =+Y14 -> 0 | AA14: =+Z14 -> 0 | AB14: =+AA14 -> 0 | AC14: =+AB14 -> 0 | AD14: =+AC14 -> 0 | AE14: =+AD14 -> 0 | ... AH14: =+AG14 -> 0 | AI14: =CB14*$F$8 -> 0 | AJ14: =CC14*$F$8 -> 4.08564 | AL14: =+ROUNDDOWN($AK14*E14,-1) -> 0 | AM14: =+ROUNDDOWN($AK14*F14,-1) -> 0 | AN14: =+ROUNDDOWN($AK14*G14,-1) -> 0 | AO14: =+ROUNDDOWN($AK14*H14,-1) -> 0 | AP14: =+ROUNDDOWN($AK14*I14,-1) -> 0 | AQ14: =+ROUNDDOWN($AK14*J14,-1) -> 0 | AR14: =+ROUNDDOWN($AK14*K14,-1) -> 0 | AS14: =+ROUNDDOWN($AK14*L14,-1) -> 0 | ... BP14: =+ROUNDDOWN($AK14*AI14,-1) -> 0 | BQ14: =SUM(AM14,AO14,BC14,BP14) -> 0 | BW14: 3.4047 | BX14: 0 | BY14: 1.9497 | BZ14: 0 | CA14: 1.455 | CB14: 0 | CC14: 6.8094
B15: 10년납 | C15: - | E15: =CC15/1200% -> 0.80995 | F15: =BW15*$F$8 -> 2.39202 | G15: =BX15*$F$8 -> 0 | H15: =BY15*$F$8 -> 2.04282 | I15: =BZ15*$F$8 -> 0 | J15: =+V15/12 -> 0.1164 | K15: =+J15 -> 0.1164 | L15: =+K15 -> 0.1164 | M15: =+L15 -> 0.1164 | N15: =+M15 -> 0.1164 | O15: =+N15 -> 0.1164 | P15: =+O15 -> 0.1164 | Q15: =+P15 -> 0.1164 | R15: =+Q15 -> 0.1164 | ... U15: =+T15 -> 0.1164 | V15: =CA15*$F$8 -> 1.3968 | W15: =+AI15/12 -> 0 | X15: =+W15 -> 0 | Y15: =+X15 -> 0 | Z15: =+Y15 -> 0 | AA15: =+Z15 -> 0 | AB15: =+AA15 -> 0 | AC15: =+AB15 -> 0 | AD15: =+AC15 -> 0 | AE15: =+AD15 -> 0 | ... AH15: =+AG15 -> 0 | AI15: =CB15*$F$8 -> 0 | AJ15: =CC15*$F$8 -> 5.83164 | AL15: =+ROUNDDOWN($AK15*E15,-1) -> 0 | AM15: =+ROUNDDOWN($AK15*F15,-1) -> 0 | AN15: =+ROUNDDOWN($AK15*G15,-1) -> 0 | AO15: =+ROUNDDOWN($AK15*H15,-1) -> 0 | AP15: =+ROUNDDOWN($AK15*I15,-1) -> 0 | AQ15: =+ROUNDDOWN($AK15*J15,-1) -> 0 | AR15: =+ROUNDDOWN($AK15*K15,-1) -> 0 | AS15: =+ROUNDDOWN($AK15*L15,-1) -> 0 | ... BP15: =+ROUNDDOWN($AK15*AI15,-1) -> 0 | BQ15: =SUM(AM15,AO15,BC15,BP15) -> 0 | BW15: 3.9867 | BX15: 0 | BY15: 3.4047 | BZ15: 0 | CA15: 2.328 | CB15: 0 | CC15: 9.7194
A16: KB 라이프 파트너 종신보험 무배당(해약환급금 일부지급형) | B16: 5년납 | C16: 1천만원이상 | E16: =CC16/1200% -> 0.4656 | F16: =BW16*$F$8 -> 2.7936 | G16: =BX16*$F$8 -> 0 | H16: =BY16*$F$8 -> 0.27936 | I16: =BZ16*$F$8 -> 0 | J16: =+V16/12 -> 0.02328 | K16: =+J16 -> 0.02328 | L16: =+K16 -> 0.02328 | M16: =+L16 -> 0.02328 | N16: =+M16 -> 0.02328 | O16: =+N16 -> 0.02328 | P16: =+O16 -> 0.02328 | Q16: =+P16 -> 0.02328 | R16: =+Q16 -> 0.02328 | ... U16: =+T16 -> 0.02328 | V16: =CA16*$F$8 -> 0.27936 | W16: =+AI16/12 -> 0 | X16: =+W16 -> 0 | Y16: =+X16 -> 0 | Z16: =+Y16 -> 0 | AA16: =+Z16 -> 0 | AB16: =+AA16 -> 0 | AC16: =+AB16 -> 0 | AD16: =+AC16 -> 0 | AE16: =+AD16 -> 0 | ... AH16: =+AG16 -> 0 | AI16: =CB16*$F$8 -> 0 | AJ16: =CC16*$F$8 -> 3.35232 | AL16: =+ROUNDDOWN($AK16*E16,-1) -> 0 | AM16: =+ROUNDDOWN($AK16*F16,-1) -> 0 | AN16: =+ROUNDDOWN($AK16*G16,-1) -> 0 | AO16: =+ROUNDDOWN($AK16*H16,-1) -> 0 | AP16: =+ROUNDDOWN($AK16*I16,-1) -> 0 | AQ16: =+ROUNDDOWN($AK16*J16,-1) -> 0 | AR16: =+ROUNDDOWN($AK16*K16,-1) -> 0 | AS16: =+ROUNDDOWN($AK16*L16,-1) -> 0 | ... BP16: =+ROUNDDOWN($AK16*AI16,-1) -> 0 | BQ16: =SUM(AM16,AO16,BC16,BP16) -> 0 | BW16: 4.656 | BX16: 0 | BY16: 0.4656 | BZ16: 0 | CA16: 0.4656 | CB16: 0 | CC16: 5.5872
C17: 3천만원이상 | E17: =CC17/1200% -> 0.5238 | F17: =BW17*$F$8 -> 3.1428 | G17: =BX17*$F$8 -> 0 | H17: =BY17*$F$8 -> 0.31428 | I17: =BZ17*$F$8 -> 0 | J17: =+V17/12 -> 0.02619 | K17: =+J17 -> 0.02619 | L17: =+K17 -> 0.02619 | M17: =+L17 -> 0.02619 | N17: =+M17 -> 0.02619 | O17: =+N17 -> 0.02619 | P17: =+O17 -> 0.02619 | Q17: =+P17 -> 0.02619 | R17: =+Q17 -> 0.02619 | ... U17: =+T17 -> 0.02619 | V17: =CA17*$F$8 -> 0.31428 | W17: =+AI17/12 -> 0 | X17: =+W17 -> 0 | Y17: =+X17 -> 0 | Z17: =+Y17 -> 0 | AA17: =+Z17 -> 0 | AB17: =+AA17 -> 0 | AC17: =+AB17 -> 0 | AD17: =+AC17 -> 0 | AE17: =+AD17 -> 0 | ... AH17: =+AG17 -> 0 | AI17: =CB17*$F$8 -> 0 | AJ17: =CC17*$F$8 -> 3.77136 | AL17: =+ROUNDDOWN($AK17*E17,-1) -> 0 | AM17: =+ROUNDDOWN($AK17*F17,-1) -> 0 | AN17: =+ROUNDDOWN($AK17*G17,-1) -> 0 | AO17: =+ROUNDDOWN($AK17*H17,-1) -> 0 | AP17: =+ROUNDDOWN($AK17*I17,-1) -> 0 | AQ17: =+ROUNDDOWN($AK17*J17,-1) -> 0 | AR17: =+ROUNDDOWN($AK17*K17,-1) -> 0 | AS17: =+ROUNDDOWN($AK17*L17,-1) -> 0 | ... BP17: =+ROUNDDOWN($AK17*AI17,-1) -> 0 | BQ17: =SUM(AM17,AO17,BC17,BP17) -> 0 | BW17: 5.238 | BX17: 0 | BY17: 0.5238 | BZ17: 0 | CA17: 0.5238 | CB17: 0 | CC17: 6.2856
C18: 5천만원이상 | E18: =CC18/1200% -> 0.582 | F18: =BW18*$F$8 -> 3.492 | G18: =BX18*$F$8 -> 0 | H18: =BY18*$F$8 -> 0.3492 | I18: =BZ18*$F$8 -> 0 | J18: =+V18/12 -> 0.0291 | K18: =+J18 -> 0.0291 | L18: =+K18 -> 0.0291 | M18: =+L18 -> 0.0291 | N18: =+M18 -> 0.0291 | O18: =+N18 -> 0.0291 | P18: =+O18 -> 0.0291 | Q18: =+P18 -> 0.0291 | R18: =+Q18 -> 0.0291 | ... U18: =+T18 -> 0.0291 | V18: =CA18*$F$8 -> 0.3492 | W18: =+AI18/12 -> 0 | X18: =+W18 -> 0 | Y18: =+X18 -> 0 | Z18: =+Y18 -> 0 | AA18: =+Z18 -> 0 | AB18: =+AA18 -> 0 | AC18: =+AB18 -> 0 | AD18: =+AC18 -> 0 | AE18: =+AD18 -> 0 | ... AH18: =+AG18 -> 0 | AI18: =CB18*$F$8 -> 0 | AJ18: =CC18*$F$8 -> 4.1904 | AL18: =+ROUNDDOWN($AK18*E18,-1) -> 0 | AM18: =+ROUNDDOWN($AK18*F18,-1) -> 0 | AN18: =+ROUNDDOWN($AK18*G18,-1) -> 0 | AO18: =+ROUNDDOWN($AK18*H18,-1) -> 0 | AP18: =+ROUNDDOWN($AK18*I18,-1) -> 0 | AQ18: =+ROUNDDOWN($AK18*J18,-1) -> 0 | AR18: =+ROUNDDOWN($AK18*K18,-1) -> 0 | AS18: =+ROUNDDOWN($AK18*L18,-1) -> 0 | ... BP18: =+ROUNDDOWN($AK18*AI18,-1) -> 0 | BQ18: =SUM(AM18,AO18,BC18,BP18) -> 0 | BW18: 5.82 | BX18: 0 | BY18: 0.582 | BZ18: 0 | CA18: 0.582 | CB18: 0 | CC18: 6.984
B19: 7년납 | C19: 1천만원이상 | E19: =CC19/1200% -> 0.4656 | F19: =BW19*$F$8 -> 2.7936 | G19: =BX19*$F$8 -> 0 | H19: =BY19*$F$8 -> 0.27936 | I19: =BZ19*$F$8 -> 0 | J19: =+V19/12 -> 0.02328 | K19: =+J19 -> 0.02328 | L19: =+K19 -> 0.02328 | M19: =+L19 -> 0.02328 | N19: =+M19 -> 0.02328 | O19: =+N19 -> 0.02328 | P19: =+O19 -> 0.02328 | Q19: =+P19 -> 0.02328 | R19: =+Q19 -> 0.02328 | ... U19: =+T19 -> 0.02328 | V19: =CA19*$F$8 -> 0.27936 | W19: =+AI19/12 -> 0 | X19: =+W19 -> 0 | Y19: =+X19 -> 0 | Z19: =+Y19 -> 0 | AA19: =+Z19 -> 0 | AB19: =+AA19 -> 0 | AC19: =+AB19 -> 0 | AD19: =+AC19 -> 0 | AE19: =+AD19 -> 0 | ... AH19: =+AG19 -> 0 | AI19: =CB19*$F$8 -> 0 | AJ19: =CC19*$F$8 -> 3.35232 | AL19: =+ROUNDDOWN($AK19*E19,-1) -> 0 | AM19: =+ROUNDDOWN($AK19*F19,-1) -> 0 | AN19: =+ROUNDDOWN($AK19*G19,-1) -> 0 | AO19: =+ROUNDDOWN($AK19*H19,-1) -> 0 | AP19: =+ROUNDDOWN($AK19*I19,-1) -> 0 | AQ19: =+ROUNDDOWN($AK19*J19,-1) -> 0 | AR19: =+ROUNDDOWN($AK19*K19,-1) -> 0 | AS19: =+ROUNDDOWN($AK19*L19,-1) -> 0 | ... BP19: =+ROUNDDOWN($AK19*AI19,-1) -> 0 | BQ19: =SUM(AM19,AO19,BC19,BP19) -> 0 | BW19: 4.656 | BX19: 0 | BY19: 0.4656 | BZ19: 0 | CA19: 0.4656 | CB19: 0 | CC19: 5.5872
C20: 3천만원이상 | E20: =CC20/1200% -> 0.5238 | F20: =BW20*$F$8 -> 3.1428 | G20: =BX20*$F$8 -> 0 | H20: =BY20*$F$8 -> 0.31428 | I20: =BZ20*$F$8 -> 0 | J20: =+V20/12 -> 0.02619 | K20: =+J20 -> 0.02619 | L20: =+K20 -> 0.02619 | M20: =+L20 -> 0.02619 | N20: =+M20 -> 0.02619 | O20: =+N20 -> 0.02619 | P20: =+O20 -> 0.02619 | Q20: =+P20 -> 0.02619 | R20: =+Q20 -> 0.02619 | ... U20: =+T20 -> 0.02619 | V20: =CA20*$F$8 -> 0.31428 | W20: =+AI20/12 -> 0 | X20: =+W20 -> 0 | Y20: =+X20 -> 0 | Z20: =+Y20 -> 0 | AA20: =+Z20 -> 0 | AB20: =+AA20 -> 0 | AC20: =+AB20 -> 0 | AD20: =+AC20 -> 0 | AE20: =+AD20 -> 0 | ... AH20: =+AG20 -> 0 | AI20: =CB20*$F$8 -> 0 | AJ20: =CC20*$F$8 -> 3.77136 | AL20: =+ROUNDDOWN($AK20*E20,-1) -> 0 | AM20: =+ROUNDDOWN($AK20*F20,-1) -> 0 | AN20: =+ROUNDDOWN($AK20*G20,-1) -> 0 | AO20: =+ROUNDDOWN($AK20*H20,-1) -> 0 | AP20: =+ROUNDDOWN($AK20*I20,-1) -> 0 | AQ20: =+ROUNDDOWN($AK20*J20,-1) -> 0 | AR20: =+ROUNDDOWN($AK20*K20,-1) -> 0 | AS20: =+ROUNDDOWN($AK20*L20,-1) -> 0 | ... BP20: =+ROUNDDOWN($AK20*AI20,-1) -> 0 | BQ20: =SUM(AM20,AO20,BC20,BP20) -> 0 | BW20: 5.238 | BX20: 0 | BY20: 0.5238 | BZ20: 0 | CA20: 0.5238 | CB20: 0 | CC20: 6.2856
C21: 5천만원이상 | E21: =CC21/1200% -> 0.582 | F21: =BW21*$F$8 -> 3.492 | G21: =BX21*$F$8 -> 0 | H21: =BY21*$F$8 -> 0.3492 | I21: =BZ21*$F$8 -> 0 | J21: =+V21/12 -> 0.0291 | K21: =+J21 -> 0.0291 | L21: =+K21 -> 0.0291 | M21: =+L21 -> 0.0291 | N21: =+M21 -> 0.0291 | O21: =+N21 -> 0.0291 | P21: =+O21 -> 0.0291 | Q21: =+P21 -> 0.0291 | R21: =+Q21 -> 0.0291 | ... U21: =+T21 -> 0.0291 | V21: =CA21*$F$8 -> 0.3492 | W21: =+AI21/12 -> 0 | X21: =+W21 -> 0 | Y21: =+X21 -> 0 | Z21: =+Y21 -> 0 | AA21: =+Z21 -> 0 | AB21: =+AA21 -> 0 | AC21: =+AB21 -> 0 | AD21: =+AC21 -> 0 | AE21: =+AD21 -> 0 | ... AH21: =+AG21 -> 0 | AI21: =CB21*$F$8 -> 0 | AJ21: =CC21*$F$8 -> 4.1904 | AL21: =+ROUNDDOWN($AK21*E21,-1) -> 0 | AM21: =+ROUNDDOWN($AK21*F21,-1) -> 0 | AN21: =+ROUNDDOWN($AK21*G21,-1) -> 0 | AO21: =+ROUNDDOWN($AK21*H21,-1) -> 0 | AP21: =+ROUNDDOWN($AK21*I21,-1) -> 0 | AQ21: =+ROUNDDOWN($AK21*J21,-1) -> 0 | AR21: =+ROUNDDOWN($AK21*K21,-1) -> 0 | AS21: =+ROUNDDOWN($AK21*L21,-1) -> 0 | ... BP21: =+ROUNDDOWN($AK21*AI21,-1) -> 0 | BQ21: =SUM(AM21,AO21,BC21,BP21) -> 0 | BW21: 5.82 | BX21: 0 | BY21: 0.582 | BZ21: 0 | CA21: 0.582 | CB21: 0 | CC21: 6.984
B22: 10년납 | C22: 1천만원이상 | E22: =CC22/1200% -> 0.744475 | F22: =BW22*$F$8 -> 4.12056 | G22: =BX22*$F$8 -> 0 | H22: =BY22*$F$8 -> 0.94284 | I22: =BZ22*$F$8 -> 0 | J22: =+V22/12 -> 0.024735 | K22: =+J22 -> 0.024735 | L22: =+K22 -> 0.024735 | M22: =+L22 -> 0.024735 | N22: =+M22 -> 0.024735 | O22: =+N22 -> 0.024735 | P22: =+O22 -> 0.024735 | Q22: =+P22 -> 0.024735 | R22: =+Q22 -> 0.024735 | ... U22: =+T22 -> 0.024735 | V22: =CA22*$F$8 -> 0.29682 | W22: =+AI22/12 -> 0 | X22: =+W22 -> 0 | Y22: =+X22 -> 0 | Z22: =+Y22 -> 0 | AA22: =+Z22 -> 0 | AB22: =+AA22 -> 0 | AC22: =+AB22 -> 0 | AD22: =+AC22 -> 0 | AE22: =+AD22 -> 0 | ... AH22: =+AG22 -> 0 | AI22: =CB22*$F$8 -> 0 | AJ22: =CC22*$F$8 -> 5.36022 | AL22: =+ROUNDDOWN($AK22*E22,-1) -> 0 | AM22: =+ROUNDDOWN($AK22*F22,-1) -> 0 | AN22: =+ROUNDDOWN($AK22*G22,-1) -> 0 | AO22: =+ROUNDDOWN($AK22*H22,-1) -> 0 | AP22: =+ROUNDDOWN($AK22*I22,-1) -> 0 | AQ22: =+ROUNDDOWN($AK22*J22,-1) -> 0 | AR22: =+ROUNDDOWN($AK22*K22,-1) -> 0 | AS22: =+ROUNDDOWN($AK22*L22,-1) -> 0 | ... BP22: =+ROUNDDOWN($AK22*AI22,-1) -> 0 | BQ22: =SUM(AM22,AO22,BC22,BP22) -> 0 | BW22: 6.8676 | BX22: 0 | BY22: 1.5714 | BZ22: 0 | CA22: 0.4947 | CB22: 0 | CC22: 8.9337
C23: 3천만원이상 | E23: =CC23/1200% -> 0.83905 | F23: =BW23*$F$8 -> 4.64436 | G23: =BX23*$F$8 -> 0 | H23: =BY23*$F$8 -> 1.06506 | I23: =BZ23*$F$8 -> 0 | J23: =+V23/12 -> 0.027645 | K23: =+J23 -> 0.027645 | L23: =+K23 -> 0.027645 | M23: =+L23 -> 0.027645 | N23: =+M23 -> 0.027645 | O23: =+N23 -> 0.027645 | P23: =+O23 -> 0.027645 | Q23: =+P23 -> 0.027645 | R23: =+Q23 -> 0.027645 | ... U23: =+T23 -> 0.027645 | V23: =CA23*$F$8 -> 0.33174 | W23: =+AI23/12 -> 0 | X23: =+W23 -> 0 | Y23: =+X23 -> 0 | Z23: =+Y23 -> 0 | AA23: =+Z23 -> 0 | AB23: =+AA23 -> 0 | AC23: =+AB23 -> 0 | AD23: =+AC23 -> 0 | AE23: =+AD23 -> 0 | ... AH23: =+AG23 -> 0 | AI23: =CB23*$F$8 -> 0 | AJ23: =CC23*$F$8 -> 6.04116 | AL23: =+ROUNDDOWN($AK23*E23,-1) -> 0 | AM23: =+ROUNDDOWN($AK23*F23,-1) -> 0 | AN23: =+ROUNDDOWN($AK23*G23,-1) -> 0 | AO23: =+ROUNDDOWN($AK23*H23,-1) -> 0 | AP23: =+ROUNDDOWN($AK23*I23,-1) -> 0 | AQ23: =+ROUNDDOWN($AK23*J23,-1) -> 0 | AR23: =+ROUNDDOWN($AK23*K23,-1) -> 0 | AS23: =+ROUNDDOWN($AK23*L23,-1) -> 0 | ... BP23: =+ROUNDDOWN($AK23*AI23,-1) -> 0 | BQ23: =SUM(AM23,AO23,BC23,BP23) -> 0 | BW23: 7.7406 | BX23: 0 | BY23: 1.7751 | BZ23: 0 | CA23: 0.5529 | CB23: 0 | CC23: 10.0686
C24: 5천만원이상 | E24: =CC24/1200% -> 0.933625 | F24: =BW24*$F$8 -> 5.16816 | G24: =BX24*$F$8 -> 0 | H24: =BY24*$F$8 -> 1.18728 | I24: =BZ24*$F$8 -> 0 | J24: =+V24/12 -> 0.030555 | K24: =+J24 -> 0.030555 | L24: =+K24 -> 0.030555 | M24: =+L24 -> 0.030555 | N24: =+M24 -> 0.030555 | O24: =+N24 -> 0.030555 | P24: =+O24 -> 0.030555 | Q24: =+P24 -> 0.030555 | R24: =+Q24 -> 0.030555 | ... U24: =+T24 -> 0.030555 | V24: =CA24*$F$8 -> 0.36666 | W24: =+AI24/12 -> 0 | X24: =+W24 -> 0 | Y24: =+X24 -> 0 | Z24: =+Y24 -> 0 | AA24: =+Z24 -> 0 | AB24: =+AA24 -> 0 | AC24: =+AB24 -> 0 | AD24: =+AC24 -> 0 | AE24: =+AD24 -> 0 | ... AH24: =+AG24 -> 0 | AI24: =CB24*$F$8 -> 0 | AJ24: =CC24*$F$8 -> 6.7221 | AL24: =+ROUNDDOWN($AK24*E24,-1) -> 0 | AM24: =+ROUNDDOWN($AK24*F24,-1) -> 0 | AN24: =+ROUNDDOWN($AK24*G24,-1) -> 0 | AO24: =+ROUNDDOWN($AK24*H24,-1) -> 0 | AP24: =+ROUNDDOWN($AK24*I24,-1) -> 0 | AQ24: =+ROUNDDOWN($AK24*J24,-1) -> 0 | AR24: =+ROUNDDOWN($AK24*K24,-1) -> 0 | AS24: =+ROUNDDOWN($AK24*L24,-1) -> 0 | ... BP24: =+ROUNDDOWN($AK24*AI24,-1) -> 0 | BQ24: =SUM(AM24,AO24,BC24,BP24) -> 0 | BW24: 8.6136 | BX24: 0 | BY24: 1.9788 | BZ24: 0 | CA24: 0.6111 | CB24: 0 | CC24: 11.2035
B25: 12년납 | C25: 1천만원이상 | E25: =CC25/1200% -> 0.8827 | F25: =BW25*$F$8 -> 4.22532 | G25: =BX25*$F$8 -> 0 | H25: =BY25*$F$8 -> 1.51902 | I25: =BZ25*$F$8 -> 0 | J25: =+V25/12 -> 0.050925 | K25: =+J25 -> 0.050925 | L25: =+K25 -> 0.050925 | M25: =+L25 -> 0.050925 | N25: =+M25 -> 0.050925 | O25: =+N25 -> 0.050925 | P25: =+O25 -> 0.050925 | Q25: =+P25 -> 0.050925 | R25: =+Q25 -> 0.050925 | ... U25: =+T25 -> 0.050925 | V25: =CA25*$F$8 -> 0.6111 | W25: =+AI25/12 -> 0 | X25: =+W25 -> 0 | Y25: =+X25 -> 0 | Z25: =+Y25 -> 0 | AA25: =+Z25 -> 0 | AB25: =+AA25 -> 0 | AC25: =+AB25 -> 0 | AD25: =+AC25 -> 0 | AE25: =+AD25 -> 0 | ... AH25: =+AG25 -> 0 | AI25: =CB25*$F$8 -> 0 | AJ25: =CC25*$F$8 -> 6.35544 | AL25: =+ROUNDDOWN($AK25*E25,-1) -> 0 | AM25: =+ROUNDDOWN($AK25*F25,-1) -> 0 | AN25: =+ROUNDDOWN($AK25*G25,-1) -> 0 | AO25: =+ROUNDDOWN($AK25*H25,-1) -> 0 | AP25: =+ROUNDDOWN($AK25*I25,-1) -> 0 | AQ25: =+ROUNDDOWN($AK25*J25,-1) -> 0 | AR25: =+ROUNDDOWN($AK25*K25,-1) -> 0 | AS25: =+ROUNDDOWN($AK25*L25,-1) -> 0 | ... BP25: =+ROUNDDOWN($AK25*AI25,-1) -> 0 | BQ25: =SUM(AM25,AO25,BC25,BP25) -> 0 | BW25: 7.0422 | BX25: 0 | BY25: 2.5317 | BZ25: 0 | CA25: 1.0185 | CB25: 0 | CC25: 10.5924
C26: 3천만원이상 | E26: =CC26/1200% -> 0.991825 | F26: =BW26*$F$8 -> 4.74912 | G26: =BX26*$F$8 -> 0 | H26: =BY26*$F$8 -> 1.71108 | I26: =BZ26*$F$8 -> 0 | J26: =+V26/12 -> 0.056745 | K26: =+J26 -> 0.056745 | L26: =+K26 -> 0.056745 | M26: =+L26 -> 0.056745 | N26: =+M26 -> 0.056745 | O26: =+N26 -> 0.056745 | P26: =+O26 -> 0.056745 | Q26: =+P26 -> 0.056745 | R26: =+Q26 -> 0.056745 | ... U26: =+T26 -> 0.056745 | V26: =CA26*$F$8 -> 0.68094 | W26: =+AI26/12 -> 0 | X26: =+W26 -> 0 | Y26: =+X26 -> 0 | Z26: =+Y26 -> 0 | AA26: =+Z26 -> 0 | AB26: =+AA26 -> 0 | AC26: =+AB26 -> 0 | AD26: =+AC26 -> 0 | AE26: =+AD26 -> 0 | ... AH26: =+AG26 -> 0 | AI26: =CB26*$F$8 -> 0 | AJ26: =CC26*$F$8 -> 7.14114 | AL26: =+ROUNDDOWN($AK26*E26,-1) -> 0 | AM26: =+ROUNDDOWN($AK26*F26,-1) -> 0 | AN26: =+ROUNDDOWN($AK26*G26,-1) -> 0 | AO26: =+ROUNDDOWN($AK26*H26,-1) -> 0 | AP26: =+ROUNDDOWN($AK26*I26,-1) -> 0 | AQ26: =+ROUNDDOWN($AK26*J26,-1) -> 0 | AR26: =+ROUNDDOWN($AK26*K26,-1) -> 0 | AS26: =+ROUNDDOWN($AK26*L26,-1) -> 0 | ... BP26: =+ROUNDDOWN($AK26*AI26,-1) -> 0 | BQ26: =SUM(AM26,AO26,BC26,BP26) -> 0 | BW26: 7.9152 | BX26: 0 | BY26: 2.8518 | BZ26: 0 | CA26: 1.1349 | CB26: 0 | CC26: 11.9019
C27: 5천만원이상 | E27: =CC27/1200% -> 1.1058 | F27: =BW27*$F$8 -> 5.29038 | G27: =BX27*$F$8 -> 0 | H27: =BY27*$F$8 -> 1.90314 | I27: =BZ27*$F$8 -> 0 | J27: =+V27/12 -> 0.06402 | K27: =+J27 -> 0.06402 | L27: =+K27 -> 0.06402 | M27: =+L27 -> 0.06402 | N27: =+M27 -> 0.06402 | O27: =+N27 -> 0.06402 | P27: =+O27 -> 0.06402 | Q27: =+P27 -> 0.06402 | R27: =+Q27 -> 0.06402 | ... U27: =+T27 -> 0.06402 | V27: =CA27*$F$8 -> 0.76824 | W27: =+AI27/12 -> 0 | X27: =+W27 -> 0 | Y27: =+X27 -> 0 | Z27: =+Y27 -> 0 | AA27: =+Z27 -> 0 | AB27: =+AA27 -> 0 | AC27: =+AB27 -> 0 | AD27: =+AC27 -> 0 | AE27: =+AD27 -> 0 | ... AH27: =+AG27 -> 0 | AI27: =CB27*$F$8 -> 0 | AJ27: =CC27*$F$8 -> 7.96176 | AL27: =+ROUNDDOWN($AK27*E27,-1) -> 0 | AM27: =+ROUNDDOWN($AK27*F27,-1) -> 0 | AN27: =+ROUNDDOWN($AK27*G27,-1) -> 0 | AO27: =+ROUNDDOWN($AK27*H27,-1) -> 0 | AP27: =+ROUNDDOWN($AK27*I27,-1) -> 0 | AQ27: =+ROUNDDOWN($AK27*J27,-1) -> 0 | AR27: =+ROUNDDOWN($AK27*K27,-1) -> 0 | AS27: =+ROUNDDOWN($AK27*L27,-1) -> 0 | ... BP27: =+ROUNDDOWN($AK27*AI27,-1) -> 0 | BQ27: =SUM(AM27,AO27,BC27,BP27) -> 0 | BW27: 8.8173 | BX27: 0 | BY27: 3.1719 | BZ27: 0 | CA27: 1.2804 | CB27: 0 | CC27: 13.2696
B28: 15년납 | C28: 1천만원이상 | E28: =CC28/1200% -> 1.020925 | F28: =BW28*$F$8 -> 4.33008 | G28: =BX28*$F$8 -> 0 | H28: =BY28*$F$8 -> 2.0952 | I28: =BZ28*$F$8 -> 0 | J28: =+V28/12 -> 0.077115 | K28: =+J28 -> 0.077115 | L28: =+K28 -> 0.077115 | M28: =+L28 -> 0.077115 | N28: =+M28 -> 0.077115 | O28: =+N28 -> 0.077115 | P28: =+O28 -> 0.077115 | Q28: =+P28 -> 0.077115 | R28: =+Q28 -> 0.077115 | ... U28: =+T28 -> 0.077115 | V28: =CA28*$F$8 -> 0.92538 | W28: =+AI28/12 -> 0 | X28: =+W28 -> 0 | Y28: =+X28 -> 0 | Z28: =+Y28 -> 0 | AA28: =+Z28 -> 0 | AB28: =+AA28 -> 0 | AC28: =+AB28 -> 0 | AD28: =+AC28 -> 0 | AE28: =+AD28 -> 0 | ... AH28: =+AG28 -> 0 | AI28: =CB28*$F$8 -> 0 | AJ28: =CC28*$F$8 -> 7.35066 | AL28: =+ROUNDDOWN($AK28*E28,-1) -> 0 | AM28: =+ROUNDDOWN($AK28*F28,-1) -> 0 | AN28: =+ROUNDDOWN($AK28*G28,-1) -> 0 | AO28: =+ROUNDDOWN($AK28*H28,-1) -> 0 | AP28: =+ROUNDDOWN($AK28*I28,-1) -> 0 | AQ28: =+ROUNDDOWN($AK28*J28,-1) -> 0 | AR28: =+ROUNDDOWN($AK28*K28,-1) -> 0 | AS28: =+ROUNDDOWN($AK28*L28,-1) -> 0 | ... BP28: =+ROUNDDOWN($AK28*AI28,-1) -> 0 | BQ28: =SUM(AM28,AO28,BC28,BP28) -> 0 | BW28: 7.2168 | BX28: 0 | BY28: 3.492 | BZ28: 0 | CA28: 1.5423 | CB28: 0 | CC28: 12.2511
C29: 3천만원이상 | E29: =CC29/1200% -> 1.14945 | F29: =BW29*$F$8 -> 4.87134 | G29: =BX29*$F$8 -> 0 | H29: =BY29*$F$8 -> 2.3571 | I29: =BZ29*$F$8 -> 0 | J29: =+V29/12 -> 0.0873 | K29: =+J29 -> 0.0873 | L29: =+K29 -> 0.0873 | M29: =+L29 -> 0.0873 | N29: =+M29 -> 0.0873 | O29: =+N29 -> 0.0873 | P29: =+O29 -> 0.0873 | Q29: =+P29 -> 0.0873 | R29: =+Q29 -> 0.0873 | ... U29: =+T29 -> 0.0873 | V29: =CA29*$F$8 -> 1.0476 | W29: =+AI29/12 -> 0 | X29: =+W29 -> 0 | Y29: =+X29 -> 0 | Z29: =+Y29 -> 0 | AA29: =+Z29 -> 0 | AB29: =+AA29 -> 0 | AC29: =+AB29 -> 0 | AD29: =+AC29 -> 0 | AE29: =+AD29 -> 0 | ... AH29: =+AG29 -> 0 | AI29: =CB29*$F$8 -> 0 | AJ29: =CC29*$F$8 -> 8.27604 | AL29: =+ROUNDDOWN($AK29*E29,-1) -> 0 | AM29: =+ROUNDDOWN($AK29*F29,-1) -> 0 | AN29: =+ROUNDDOWN($AK29*G29,-1) -> 0 | AO29: =+ROUNDDOWN($AK29*H29,-1) -> 0 | AP29: =+ROUNDDOWN($AK29*I29,-1) -> 0 | AQ29: =+ROUNDDOWN($AK29*J29,-1) -> 0 | AR29: =+ROUNDDOWN($AK29*K29,-1) -> 0 | AS29: =+ROUNDDOWN($AK29*L29,-1) -> 0 | ... BP29: =+ROUNDDOWN($AK29*AI29,-1) -> 0 | BQ29: =SUM(AM29,AO29,BC29,BP29) -> 0 | BW29: 8.1189 | BX29: 0 | BY29: 3.9285 | BZ29: 0 | CA29: 1.746 | CB29: 0 | CC29: 13.7934
C30: 5천만원이상 | E30: =CC30/1200% -> 1.277975 | F30: =BW30*$F$8 -> 5.4126 | G30: =BX30*$F$8 -> 0 | H30: =BY30*$F$8 -> 2.619 | I30: =BZ30*$F$8 -> 0 | J30: =+V30/12 -> 0.097485 | K30: =+J30 -> 0.097485 | L30: =+K30 -> 0.097485 | M30: =+L30 -> 0.097485 | N30: =+M30 -> 0.097485 | O30: =+N30 -> 0.097485 | P30: =+O30 -> 0.097485 | Q30: =+P30 -> 0.097485 | R30: =+Q30 -> 0.097485 | ... U30: =+T30 -> 0.097485 | V30: =CA30*$F$8 -> 1.16982 | W30: =+AI30/12 -> 0 | X30: =+W30 -> 0 | Y30: =+X30 -> 0 | Z30: =+Y30 -> 0 | AA30: =+Z30 -> 0 | AB30: =+AA30 -> 0 | AC30: =+AB30 -> 0 | AD30: =+AC30 -> 0 | AE30: =+AD30 -> 0 | ... AH30: =+AG30 -> 0 | AI30: =CB30*$F$8 -> 0 | AJ30: =CC30*$F$8 -> 9.20142 | AL30: =+ROUNDDOWN($AK30*E30,-1) -> 0 | AM30: =+ROUNDDOWN($AK30*F30,-1) -> 0 | AN30: =+ROUNDDOWN($AK30*G30,-1) -> 0 | AO30: =+ROUNDDOWN($AK30*H30,-1) -> 0 | AP30: =+ROUNDDOWN($AK30*I30,-1) -> 0 | AQ30: =+ROUNDDOWN($AK30*J30,-1) -> 0 | AR30: =+ROUNDDOWN($AK30*K30,-1) -> 0 | AS30: =+ROUNDDOWN($AK30*L30,-1) -> 0 | ... BP30: =+ROUNDDOWN($AK30*AI30,-1) -> 0 | BQ30: =SUM(AM30,AO30,BC30,BP30) -> 0 | BW30: 9.021 | BX30: 0 | BY30: 4.365 | BZ30: 0 | CA30: 1.9497 | CB30: 0 | CC30: 15.3357
B31: 20년납이상 | C31: 1천만원이상 | E31: =CC31/1200% -> 1.261 | F31: =BW31*$F$8 -> 4.33008 | G31: =BX31*$F$8 -> 0 | H31: =BY31*$F$8 -> 2.4444 | I31: =BZ31*$F$8 -> 0 | J31: =+V31/12 -> 0.19206 | K31: =+J31 -> 0.19206 | L31: =+K31 -> 0.19206 | M31: =+L31 -> 0.19206 | N31: =+M31 -> 0.19206 | O31: =+N31 -> 0.19206 | P31: =+O31 -> 0.19206 | Q31: =+P31 -> 0.19206 | R31: =+Q31 -> 0.19206 | ... U31: =+T31 -> 0.19206 | V31: =CA31*$F$8 -> 2.30472 | W31: =+AI31/12 -> 0 | X31: =+W31 -> 0 | Y31: =+X31 -> 0 | Z31: =+Y31 -> 0 | AA31: =+Z31 -> 0 | AB31: =+AA31 -> 0 | AC31: =+AB31 -> 0 | AD31: =+AC31 -> 0 | AE31: =+AD31 -> 0 | ... AH31: =+AG31 -> 0 | AI31: =CB31*$F$8 -> 0 | AJ31: =CC31*$F$8 -> 9.0792 | AL31: =+ROUNDDOWN($AK31*E31,-1) -> 0 | AM31: =+ROUNDDOWN($AK31*F31,-1) -> 0 | AN31: =+ROUNDDOWN($AK31*G31,-1) -> 0 | AO31: =+ROUNDDOWN($AK31*H31,-1) -> 0 | AP31: =+ROUNDDOWN($AK31*I31,-1) -> 0 | AQ31: =+ROUNDDOWN($AK31*J31,-1) -> 0 | AR31: =+ROUNDDOWN($AK31*K31,-1) -> 0 | AS31: =+ROUNDDOWN($AK31*L31,-1) -> 0 | ... BP31: =+ROUNDDOWN($AK31*AI31,-1) -> 0 | BQ31: =SUM(AM31,AO31,BC31,BP31) -> 0 | BW31: 7.2168 | BX31: 0 | BY31: 4.074 | BZ31: 0 | CA31: 3.8412 | CB31: 0 | CC31: 15.132
C32: 3천만원이상 | E32: =CC32/1200% -> 1.4162 | F32: =BW32*$F$8 -> 4.87134 | G32: =BX32*$F$8 -> 0 | H32: =BY32*$F$8 -> 2.74122 | I32: =BZ32*$F$8 -> 0 | J32: =+V32/12 -> 0.21534 | K32: =+J32 -> 0.21534 | L32: =+K32 -> 0.21534 | M32: =+L32 -> 0.21534 | N32: =+M32 -> 0.21534 | O32: =+N32 -> 0.21534 | P32: =+O32 -> 0.21534 | Q32: =+P32 -> 0.21534 | R32: =+Q32 -> 0.21534 | ... U32: =+T32 -> 0.21534 | V32: =CA32*$F$8 -> 2.58408 | W32: =+AI32/12 -> 0 | X32: =+W32 -> 0 | Y32: =+X32 -> 0 | Z32: =+Y32 -> 0 | AA32: =+Z32 -> 0 | AB32: =+AA32 -> 0 | AC32: =+AB32 -> 0 | AD32: =+AC32 -> 0 | AE32: =+AD32 -> 0 | ... AH32: =+AG32 -> 0 | AI32: =CB32*$F$8 -> 0 | AJ32: =CC32*$F$8 -> 10.19664 | AL32: =+ROUNDDOWN($AK32*E32,-1) -> 0 | AM32: =+ROUNDDOWN($AK32*F32,-1) -> 0 | AN32: =+ROUNDDOWN($AK32*G32,-1) -> 0 | AO32: =+ROUNDDOWN($AK32*H32,-1) -> 0 | AP32: =+ROUNDDOWN($AK32*I32,-1) -> 0 | AQ32: =+ROUNDDOWN($AK32*J32,-1) -> 0 | AR32: =+ROUNDDOWN($AK32*K32,-1) -> 0 | AS32: =+ROUNDDOWN($AK32*L32,-1) -> 0 | ... BP32: =+ROUNDDOWN($AK32*AI32,-1) -> 0 | BQ32: =SUM(AM32,AO32,BC32,BP32) -> 0 | BW32: 8.1189 | BX32: 0 | BY32: 4.5687 | BZ32: 0 | CA32: 4.3068 | CB32: 0 | CC32: 16.9944
C33: 5천만원이상 | E33: =CC33/1200% -> 1.57625 | F33: =BW33*$F$8 -> 5.4126 | G33: =BX33*$F$8 -> 0 | H33: =BY33*$F$8 -> 3.0555 | I33: =BZ33*$F$8 -> 0 | J33: =+V33/12 -> 0.240075 | K33: =+J33 -> 0.240075 | L33: =+K33 -> 0.240075 | M33: =+L33 -> 0.240075 | N33: =+M33 -> 0.240075 | O33: =+N33 -> 0.240075 | P33: =+O33 -> 0.240075 | Q33: =+P33 -> 0.240075 | R33: =+Q33 -> 0.240075 | ... U33: =+T33 -> 0.240075 | V33: =CA33*$F$8 -> 2.8809 | W33: =+AI33/12 -> 0 | X33: =+W33 -> 0 | Y33: =+X33 -> 0 | Z33: =+Y33 -> 0 | AA33: =+Z33 -> 0 | AB33: =+AA33 -> 0 | AC33: =+AB33 -> 0 | AD33: =+AC33 -> 0 | AE33: =+AD33 -> 0 | ... AH33: =+AG33 -> 0 | AI33: =CB33*$F$8 -> 0 | AJ33: =CC33*$F$8 -> 11.349 | AL33: =+ROUNDDOWN($AK33*E33,-1) -> 0 | AM33: =+ROUNDDOWN($AK33*F33,-1) -> 0 | AN33: =+ROUNDDOWN($AK33*G33,-1) -> 0 | AO33: =+ROUNDDOWN($AK33*H33,-1) -> 0 | AP33: =+ROUNDDOWN($AK33*I33,-1) -> 0 | AQ33: =+ROUNDDOWN($AK33*J33,-1) -> 0 | AR33: =+ROUNDDOWN($AK33*K33,-1) -> 0 | AS33: =+ROUNDDOWN($AK33*L33,-1) -> 0 | ... BP33: =+ROUNDDOWN($AK33*AI33,-1) -> 0 | BQ33: =SUM(AM33,AO33,BC33,BP33) -> 0 | BW33: 9.021 | BX33: 0 | BY33: 5.0925 | BZ33: 0 | CA33: 4.8015 | CB33: 0 | CC33: 18.915
A34: KB Trust 라이프 파트너 종신보험 무배당 (해약환급금 일부지급형) | B34: 5년납 | C34: 3천만원이상 | E34: =CC34/1200% -> 0.5238 | F34: =BW34*$F$8 -> 3.1428 | G34: =BX34*$F$8 -> 0 | H34: =BY34*$F$8 -> 0.31428 | I34: =BZ34*$F$8 -> 0 | J34: =+V34/12 -> 0.02619 | K34: =+J34 -> 0.02619 | L34: =+K34 -> 0.02619 | M34: =+L34 -> 0.02619 | N34: =+M34 -> 0.02619 | O34: =+N34 -> 0.02619 | P34: =+O34 -> 0.02619 | Q34: =+P34 -> 0.02619 | R34: =+Q34 -> 0.02619 | ... U34: =+T34 -> 0.02619 | V34: =CA34*$F$8 -> 0.31428 | W34: =+AI34/12 -> 0 | X34: =+W34 -> 0 | Y34: =+X34 -> 0 | Z34: =+Y34 -> 0 | AA34: =+Z34 -> 0 | AB34: =+AA34 -> 0 | AC34: =+AB34 -> 0 | AD34: =+AC34 -> 0 | AE34: =+AD34 -> 0 | ... AH34: =+AG34 -> 0 | AI34: =CB34*$F$8 -> 0 | AJ34: =CC34*$F$8 -> 3.77136 | AL34: =+ROUNDDOWN($AK34*E34,-1) -> 0 | AM34: =+ROUNDDOWN($AK34*F34,-1) -> 0 | AN34: =+ROUNDDOWN($AK34*G34,-1) -> 0 | AO34: =+ROUNDDOWN($AK34*H34,-1) -> 0 | AP34: =+ROUNDDOWN($AK34*I34,-1) -> 0 | AQ34: =+ROUNDDOWN($AK34*J34,-1) -> 0 | AR34: =+ROUNDDOWN($AK34*K34,-1) -> 0 | AS34: =+ROUNDDOWN($AK34*L34,-1) -> 0 | ... BP34: =+ROUNDDOWN($AK34*AI34,-1) -> 0 | BQ34: =SUM(AM34,AO34,BC34,BP34) -> 0 | BW34: 5.238 | BX34: 0 | BY34: 0.5238 | BZ34: 0 | CA34: 0.5238 | CB34: 0 | CC34: 6.2856
C35: 5천만원이상 | E35: =CC35/1200% -> 0.582 | F35: =BW35*$F$8 -> 3.492 | G35: =BX35*$F$8 -> 0 | H35: =BY35*$F$8 -> 0.3492 | I35: =BZ35*$F$8 -> 0 | J35: =+V35/12 -> 0.0291 | K35: =+J35 -> 0.0291 | L35: =+K35 -> 0.0291 | M35: =+L35 -> 0.0291 | N35: =+M35 -> 0.0291 | O35: =+N35 -> 0.0291 | P35: =+O35 -> 0.0291 | Q35: =+P35 -> 0.0291 | R35: =+Q35 -> 0.0291 | ... U35: =+T35 -> 0.0291 | V35: =CA35*$F$8 -> 0.3492 | W35: =+AI35/12 -> 0 | X35: =+W35 -> 0 | Y35: =+X35 -> 0 | Z35: =+Y35 -> 0 | AA35: =+Z35 -> 0 | AB35: =+AA35 -> 0 | AC35: =+AB35 -> 0 | AD35: =+AC35 -> 0 | AE35: =+AD35 -> 0 | ... AH35: =+AG35 -> 0 | AI35: =CB35*$F$8 -> 0 | AJ35: =CC35*$F$8 -> 4.1904 | AL35: =+ROUNDDOWN($AK35*E35,-1) -> 0 | AM35: =+ROUNDDOWN($AK35*F35,-1) -> 0 | AN35: =+ROUNDDOWN($AK35*G35,-1) -> 0 | AO35: =+ROUNDDOWN($AK35*H35,-1) -> 0 | AP35: =+ROUNDDOWN($AK35*I35,-1) -> 0 | AQ35: =+ROUNDDOWN($AK35*J35,-1) -> 0 | AR35: =+ROUNDDOWN($AK35*K35,-1) -> 0 | AS35: =+ROUNDDOWN($AK35*L35,-1) -> 0 | ... BP35: =+ROUNDDOWN($AK35*AI35,-1) -> 0 | BQ35: =SUM(AM35,AO35,BC35,BP35) -> 0 | BW35: 5.82 | BX35: 0 | BY35: 0.582 | BZ35: 0 | CA35: 0.582 | CB35: 0 | CC35: 6.984
B36: 7년납 | C36: 3천만원이상 | E36: =CC36/1200% -> 0.5238 | F36: =BW36*$F$8 -> 3.1428 | G36: =BX36*$F$8 -> 0 | H36: =BY36*$F$8 -> 0.31428 | I36: =BZ36*$F$8 -> 0 | J36: =+V36/12 -> 0.02619 | K36: =+J36 -> 0.02619 | L36: =+K36 -> 0.02619 | M36: =+L36 -> 0.02619 | N36: =+M36 -> 0.02619 | O36: =+N36 -> 0.02619 | P36: =+O36 -> 0.02619 | Q36: =+P36 -> 0.02619 | R36: =+Q36 -> 0.02619 | ... U36: =+T36 -> 0.02619 | V36: =CA36*$F$8 -> 0.31428 | W36: =+AI36/12 -> 0 | X36: =+W36 -> 0 | Y36: =+X36 -> 0 | Z36: =+Y36 -> 0 | AA36: =+Z36 -> 0 | AB36: =+AA36 -> 0 | AC36: =+AB36 -> 0 | AD36: =+AC36 -> 0 | AE36: =+AD36 -> 0 | ... AH36: =+AG36 -> 0 | AI36: =CB36*$F$8 -> 0 | AJ36: =CC36*$F$8 -> 3.77136 | AL36: =+ROUNDDOWN($AK36*E36,-1) -> 0 | AM36: =+ROUNDDOWN($AK36*F36,-1) -> 0 | AN36: =+ROUNDDOWN($AK36*G36,-1) -> 0 | AO36: =+ROUNDDOWN($AK36*H36,-1) -> 0 | AP36: =+ROUNDDOWN($AK36*I36,-1) -> 0 | AQ36: =+ROUNDDOWN($AK36*J36,-1) -> 0 | AR36: =+ROUNDDOWN($AK36*K36,-1) -> 0 | AS36: =+ROUNDDOWN($AK36*L36,-1) -> 0 | ... BP36: =+ROUNDDOWN($AK36*AI36,-1) -> 0 | BQ36: =SUM(AM36,AO36,BC36,BP36) -> 0 | BW36: 5.238 | BX36: 0 | BY36: 0.5238 | BZ36: 0 | CA36: 0.5238 | CB36: 0 | CC36: 6.2856
C37: 5천만원이상 | E37: =CC37/1200% -> 0.582 | F37: =BW37*$F$8 -> 3.492 | G37: =BX37*$F$8 -> 0 | H37: =BY37*$F$8 -> 0.3492 | I37: =BZ37*$F$8 -> 0 | J37: =+V37/12 -> 0.0291 | K37: =+J37 -> 0.0291 | L37: =+K37 -> 0.0291 | M37: =+L37 -> 0.0291 | N37: =+M37 -> 0.0291 | O37: =+N37 -> 0.0291 | P37: =+O37 -> 0.0291 | Q37: =+P37 -> 0.0291 | R37: =+Q37 -> 0.0291 | ... U37: =+T37 -> 0.0291 | V37: =CA37*$F$8 -> 0.3492 | W37: =+AI37/12 -> 0 | X37: =+W37 -> 0 | Y37: =+X37 -> 0 | Z37: =+Y37 -> 0 | AA37: =+Z37 -> 0 | AB37: =+AA37 -> 0 | AC37: =+AB37 -> 0 | AD37: =+AC37 -> 0 | AE37: =+AD37 -> 0 | ... AH37: =+AG37 -> 0 | AI37: =CB37*$F$8 -> 0 | AJ37: =CC37*$F$8 -> 4.1904 | AL37: =+ROUNDDOWN($AK37*E37,-1) -> 0 | AM37: =+ROUNDDOWN($AK37*F37,-1) -> 0 | AN37: =+ROUNDDOWN($AK37*G37,-1) -> 0 | AO37: =+ROUNDDOWN($AK37*H37,-1) -> 0 | AP37: =+ROUNDDOWN($AK37*I37,-1) -> 0 | AQ37: =+ROUNDDOWN($AK37*J37,-1) -> 0 | AR37: =+ROUNDDOWN($AK37*K37,-1) -> 0 | AS37: =+ROUNDDOWN($AK37*L37,-1) -> 0 | ... BP37: =+ROUNDDOWN($AK37*AI37,-1) -> 0 | BQ37: =SUM(AM37,AO37,BC37,BP37) -> 0 | BW37: 5.82 | BX37: 0 | BY37: 0.582 | BZ37: 0 | CA37: 0.582 | CB37: 0 | CC37: 6.984
B38: 10년납 | C38: 3천만원이상 | E38: =CC38/1200% -> 0.83905 | F38: =BW38*$F$8 -> 4.64436 | G38: =BX38*$F$8 -> 0 | H38: =BY38*$F$8 -> 1.06506 | I38: =BZ38*$F$8 -> 0 | J38: =+V38/12 -> 0.027645 | K38: =+J38 -> 0.027645 | L38: =+K38 -> 0.027645 | M38: =+L38 -> 0.027645 | N38: =+M38 -> 0.027645 | O38: =+N38 -> 0.027645 | P38: =+O38 -> 0.027645 | Q38: =+P38 -> 0.027645 | R38: =+Q38 -> 0.027645 | ... U38: =+T38 -> 0.027645 | V38: =CA38*$F$8 -> 0.33174 | W38: =+AI38/12 -> 0 | X38: =+W38 -> 0 | Y38: =+X38 -> 0 | Z38: =+Y38 -> 0 | AA38: =+Z38 -> 0 | AB38: =+AA38 -> 0 | AC38: =+AB38 -> 0 | AD38: =+AC38 -> 0 | AE38: =+AD38 -> 0 | ... AH38: =+AG38 -> 0 | AI38: =CB38*$F$8 -> 0 | AJ38: =CC38*$F$8 -> 6.04116 | AL38: =+ROUNDDOWN($AK38*E38,-1) -> 0 | AM38: =+ROUNDDOWN($AK38*F38,-1) -> 0 | AN38: =+ROUNDDOWN($AK38*G38,-1) -> 0 | AO38: =+ROUNDDOWN($AK38*H38,-1) -> 0 | AP38: =+ROUNDDOWN($AK38*I38,-1) -> 0 | AQ38: =+ROUNDDOWN($AK38*J38,-1) -> 0 | AR38: =+ROUNDDOWN($AK38*K38,-1) -> 0 | AS38: =+ROUNDDOWN($AK38*L38,-1) -> 0 | ... BP38: =+ROUNDDOWN($AK38*AI38,-1) -> 0 | BQ38: =SUM(AM38,AO38,BC38,BP38) -> 0 | BW38: 7.7406 | BX38: 0 | BY38: 1.7751 | BZ38: 0 | CA38: 0.5529 | CB38: 0 | CC38: 10.0686
C39: 5천만원이상 | E39: =CC39/1200% -> 0.933625 | F39: =BW39*$F$8 -> 5.16816 | G39: =BX39*$F$8 -> 0 | H39: =BY39*$F$8 -> 1.18728 | I39: =BZ39*$F$8 -> 0 | J39: =+V39/12 -> 0.030555 | K39: =+J39 -> 0.030555 | L39: =+K39 -> 0.030555 | M39: =+L39 -> 0.030555 | N39: =+M39 -> 0.030555 | O39: =+N39 -> 0.030555 | P39: =+O39 -> 0.030555 | Q39: =+P39 -> 0.030555 | R39: =+Q39 -> 0.030555 | ... U39: =+T39 -> 0.030555 | V39: =CA39*$F$8 -> 0.36666 | W39: =+AI39/12 -> 0 | X39: =+W39 -> 0 | Y39: =+X39 -> 0 | Z39: =+Y39 -> 0 | AA39: =+Z39 -> 0 | AB39: =+AA39 -> 0 | AC39: =+AB39 -> 0 | AD39: =+AC39 -> 0 | AE39: =+AD39 -> 0 | ... AH39: =+AG39 -> 0 | AI39: =CB39*$F$8 -> 0 | AJ39: =CC39*$F$8 -> 6.7221 | AL39: =+ROUNDDOWN($AK39*E39,-1) -> 0 | AM39: =+ROUNDDOWN($AK39*F39,-1) -> 0 | AN39: =+ROUNDDOWN($AK39*G39,-1) -> 0 | AO39: =+ROUNDDOWN($AK39*H39,-1) -> 0 | AP39: =+ROUNDDOWN($AK39*I39,-1) -> 0 | AQ39: =+ROUNDDOWN($AK39*J39,-1) -> 0 | AR39: =+ROUNDDOWN($AK39*K39,-1) -> 0 | AS39: =+ROUNDDOWN($AK39*L39,-1) -> 0 | ... BP39: =+ROUNDDOWN($AK39*AI39,-1) -> 0 | BQ39: =SUM(AM39,AO39,BC39,BP39) -> 0 | BW39: 8.6136 | BX39: 0 | BY39: 1.9788 | BZ39: 0 | CA39: 0.6111 | CB39: 0 | CC39: 11.2035
B40: 12년납 | C40: 3천만원이상 | E40: =CC40/1200% -> 0.991825 | F40: =BW40*$F$8 -> 4.74912 | G40: =BX40*$F$8 -> 0 | H40: =BY40*$F$8 -> 1.71108 | I40: =BZ40*$F$8 -> 0 | J40: =+V40/12 -> 0.056745 | K40: =+J40 -> 0.056745 | L40: =+K40 -> 0.056745 | M40: =+L40 -> 0.056745 | N40: =+M40 -> 0.056745 | O40: =+N40 -> 0.056745 | P40: =+O40 -> 0.056745 | Q40: =+P40 -> 0.056745 | R40: =+Q40 -> 0.056745 | ... U40: =+T40 -> 0.056745 | V40: =CA40*$F$8 -> 0.68094 | W40: =+AI40/12 -> 0 | X40: =+W40 -> 0 | Y40: =+X40 -> 0 | Z40: =+Y40 -> 0 | AA40: =+Z40 -> 0 | AB40: =+AA40 -> 0 | AC40: =+AB40 -> 0 | AD40: =+AC40 -> 0 | AE40: =+AD40 -> 0 | ... AH40: =+AG40 -> 0 | AI40: =CB40*$F$8 -> 0 | AJ40: =CC40*$F$8 -> 7.14114 | AL40: =+ROUNDDOWN($AK40*E40,-1) -> 0 | AM40: =+ROUNDDOWN($AK40*F40,-1) -> 0 | AN40: =+ROUNDDOWN($AK40*G40,-1) -> 0 | AO40: =+ROUNDDOWN($AK40*H40,-1) -> 0 | AP40: =+ROUNDDOWN($AK40*I40,-1) -> 0 | AQ40: =+ROUNDDOWN($AK40*J40,-1) -> 0 | AR40: =+ROUNDDOWN($AK40*K40,-1) -> 0 | AS40: =+ROUNDDOWN($AK40*L40,-1) -> 0 | ... BP40: =+ROUNDDOWN($AK40*AI40,-1) -> 0 | BQ40: =SUM(AM40,AO40,BC40,BP40) -> 0 | BW40: 7.9152 | BX40: 0 | BY40: 2.8518 | BZ40: 0 | CA40: 1.1349 | CB40: 0 | CC40: 11.9019
C41: 5천만원이상 | E41: =CC41/1200% -> 1.1058 | F41: =BW41*$F$8 -> 5.29038 | G41: =BX41*$F$8 -> 0 | H41: =BY41*$F$8 -> 1.90314 | I41: =BZ41*$F$8 -> 0 | J41: =+V41/12 -> 0.06402 | K41: =+J41 -> 0.06402 | L41: =+K41 -> 0.06402 | M41: =+L41 -> 0.06402 | N41: =+M41 -> 0.06402 | O41: =+N41 -> 0.06402 | P41: =+O41 -> 0.06402 | Q41: =+P41 -> 0.06402 | R41: =+Q41 -> 0.06402 | ... U41: =+T41 -> 0.06402 | V41: =CA41*$F$8 -> 0.76824 | W41: =+AI41/12 -> 0 | X41: =+W41 -> 0 | Y41: =+X41 -> 0 | Z41: =+Y41 -> 0 | AA41: =+Z41 -> 0 | AB41: =+AA41 -> 0 | AC41: =+AB41 -> 0 | AD41: =+AC41 -> 0 | AE41: =+AD41 -> 0 | ... AH41: =+AG41 -> 0 | AI41: =CB41*$F$8 -> 0 | AJ41: =CC41*$F$8 -> 7.96176 | AL41: =+ROUNDDOWN($AK41*E41,-1) -> 0 | AM41: =+ROUNDDOWN($AK41*F41,-1) -> 0 | AN41: =+ROUNDDOWN($AK41*G41,-1) -> 0 | AO41: =+ROUNDDOWN($AK41*H41,-1) -> 0 | AP41: =+ROUNDDOWN($AK41*I41,-1) -> 0 | AQ41: =+ROUNDDOWN($AK41*J41,-1) -> 0 | AR41: =+ROUNDDOWN($AK41*K41,-1) -> 0 | AS41: =+ROUNDDOWN($AK41*L41,-1) -> 0 | ... BP41: =+ROUNDDOWN($AK41*AI41,-1) -> 0 | BQ41: =SUM(AM41,AO41,BC41,BP41) -> 0 | BW41: 8.8173 | BX41: 0 | BY41: 3.1719 | BZ41: 0 | CA41: 1.2804 | CB41: 0 | CC41: 13.2696
...

Sheet 미래에셋
A1: [미래에셋생명] "상품별 MIP 比 지급률 예시"
A2: 1. 주계약의 보험료 기준 예시이며, 특약 부가 시 지급률 변동될 수 있음
A3: 2. 회사 전체 업적 달성 구간, 실제 산출 대상 보험료 및 특약별 지급률, 제휴사 수수료 정책 등에 따라 변동될 수 있음
A4: 3. 보수 지급액 = 월납화 초회 보험료 x 지급률*(지급률 예시 참조)
A5: ※ 제휴사 전개 프로모션/시상은 본 예시에서 제외 | IM5: * 일시납/전략보장 상품은 13~15회차 분급
DV6: =SUBTOTAL(9,DV12:DV253) -> 0 | DW6: =SUBTOTAL(9,DW12:DW253) -> 0 | DX6: =SUBTOTAL(9,DX12:DX253) -> 0 | DY6: =SUBTOTAL(9,DY12:DY253) -> 0 | DZ6: =SUBTOTAL(9,DZ12:DZ253) -> 0 | EA6: =SUBTOTAL(9,EA12:EA253) -> 0 | EB6: =SUBTOTAL(9,EB12:EB253) -> 0 | EC6: =SUBTOTAL(9,EC12:EC253) -> 0 | ... IM6: =SUBTOTAL(9,IM12:IM253) -> 0
A7: 상품분류 | B7: 상품명 | C7: 구분 | D7: 납입기간 | E7: 환산율 | F7: 2025년 FC 수수료 | DX7: 수당확인 | IS7: 지사보수
F8: 0.6 | DV8: 모집업적 | DW8: 환산업적 | IS8: 월납화 보험료 x 하기 지급률
F9: 초년도 | Z9: 2차년도 | AM9: 3차년도 | AN9: 4차년도 | DT9: 38~120회차 | DU9: FC계 | DV9: (월초P) | DX9: 초년도 | ER9: 2차년도 | FE9: 3차년도 | FF9: 4차년도 | IM9: FC계 | IS9: 초년도 | IU9: 2차년도* | IV9: 3차년도 | IW9: 4차년도 이후 | IY9: Total
F10: 익월 | G10: 7회차 | H10: 8회차 | I10: 9회차 | J10: 10회차 | K10: 11회차 | L10: 12회차 | M10: 7~12회차 분급 | N10: 13회차 | O10: 14회차 | P10: 15회차 | Q10: 16회차 | R10: 17회차 | S10: 18회차 | T10: 19회차 | U10: 20회차 | V10: 21회차 | W10: 22회차 | X10: 23회차 | Y10: 24회차 | Z10: 13~24회차 분급 | AA10: 25회차 | AB10: 26회차 | AC10: 27회차 | AD10: 28회차 | AE10: 29회차 | AF10: 30회차 | AG10: 31회차 | AH10: 32회차 | AI10: 33회차 | AJ10: 34회차 | AK10: 35회차 | AL10: 36회차 | AM10: 25~36회차 분급 | AN10: 37회차 | AO10: 38회차 | AP10: 39회차 | AQ10: 40회차 | AR10: 41회차 | AS10: 42회차 | AT10: 43회차 | AU10: 44회차 | AV10: 45회차 | AW10: 46회차 | AX10: 47회차 | AY10: 48회차 | AZ10: 49회차 | BA10: 50회차 | BB10: 51회차 | BC10: 52회차 | BD10: 53회차 | BE10: 54회차 | BF10: 55회차 | BG10: 56회차 | BH10: 57회차 | BI10: 58회차 | BJ10: 59회차 | BK10: 60회차 | BL10: 61회차 | BM10: 62회차 | BN10: 63회차 | BO10: 64회차 | BP10: 65회차 | BQ10: 66회차 | BR10: 67회차 | BS10: 68회차 | BT10: 69회차 | BU10: 70회차 | BV10: 71회차 | BW10: 72회차 | BX10: 73회차 | BY10: 74회차 | BZ10: 75회차 | CA10: 76회차 | CB10: 77회차 | CC10: 78회차 | CD10: 79회차 | CE10: 80회차 | CF10: 81회차 | CG10: 82회차 | CH10: 83회차 | CI10: 84회차 | CJ10: 85회차 | CK10: 86회차 | CL10: 87회차 | CM10: 88회차 | CN10: 89회차 | CO10: 90회차 | CP10: 91회차 | CQ10: 92회차 | CR10: 93회차 | CS10: 94회차 | CT10: 95회차 | CU10: 96회차 | CV10: 97회차 | CW10: 98회차 | CX10: 99회차 | CY10: 100회차 | CZ10: 101회차 | DA10: 102회차 | DB10: 103회차 | DC10: 104회차 | DD10: 105회차 | DE10: 106회차 | DF10: 107회차 | DG10: 108회차 | DH10: 109회차 | DI10: 110회차 | DJ10: 111회차 | DK10: 112회차 | DL10: 113회차 | DM10: 114회차 | DN10: 115회차 | DO10: 116회차 | DP10: 117회차 | DQ10: 118회차 | DR10: 119회차 | DS10: 120회차 | DT10: 분급 | DX10: 익월 | DY10: 7회차 | DZ10: 8회차 | EA10: 9회차 | EB10: 10회차 | EC10: 11회차 | ED10: 12회차 | EE10: 7~12회차 분급 | EF10: 13회차 | EG10: 14회차 | EH10: 15회차 | EI10: 16회차 | EJ10: 17회차 | EK10: 18회차 | EL10: 19회차 | EM10: 20회차 | EN10: 21회차 | EO10: 22회차 | EP10: 23회차 | EQ10: 24회차 | ER10: 13~24회차 분급 | ES10: 25회차 | ET10: 26회차 | EU10: 27회차 | EV10: 28회차 | EW10: 29회차 | EX10: 30회차 | EY10: 31회차 | EZ10: 32회차 | FA10: 33회차 | FB10: 34회차 | FC10: 35회차 | FD10: 36회차 | FE10: 25~36회차 분급 | FF10: 37회차 | FG10: 38회차 | FH10: 39회차 | FI10: 40회차 | FJ10: 41회차 | FK10: 42회차 | FL10: 43회차 | FM10: 44회차 | FN10: 45회차 | FO10: 46회차 | FP10: 47회차 | FQ10: 48회차 | FR10: 49회차 | FS10: 50회차 | FT10: 51회차 | FU10: 52회차 | FV10: 53회차 | FW10: 54회차 | FX10: 55회차 | FY10: 56회차 | FZ10: 57회차 | GA10: 58회차 | GB10: 59회차 | GC10: 60회차 | GD10: 61회차 | GE10: 62회차 | GF10: 63회차 | GG10: 64회차 | GH10: 65회차 | GI10: 66회차 | GJ10: 67회차 | GK10: 68회차 | GL10: 69회차 | GM10: 70회차 | GN10: 71회차 | GO10: 72회차 | GP10: 73회차 | GQ10: 74회차 | GR10: 75회차 | GS10: 76회차 | GT10: 77회차 | GU10: 78회차 | GV10: 79회차 | GW10: 80회차 | GX10: 81회차 | GY10: 82회차 | GZ10: 83회차 | HA10: 84회차 | HB10: 85회차 | HC10: 86회차 | HD10: 87회차 | HE10: 88회차 | HF10: 89회차 | HG10: 90회차 | HH10: 91회차 | HI10: 92회차 | HJ10: 93회차 | HK10: 94회차 | HL10: 95회차 | HM10: 96회차 | HN10: 97회차 | HO10: 98회차 | HP10: 99회차 | HQ10: 100회차 | HR10: 101회차 | HS10: 102회차 | HT10: 103회차 | HU10: 104회차 | HV10: 105회차 | HW10: 106회차 | HX10: 107회차 | HY10: 108회차 | HZ10: 109회차 | IA10: 110회차 | IB10: 111회차 | IC10: 112회차 | ID10: 113회차 | IE10: 114회차 | IF10: 115회차 | IG10: 116회차 | IH10: 117회차 | II10: 118회차 | IJ10: 119회차 | IK10: 120회차 | IL10: 38~120회차 분급 | IS10: 익월 | IT10: 7~12회차 분급 | IU10: 13~24회차 분급 | IV10: 25~36회차 분급 | IW10: 37회차 | IX10: 38~120회차 분급
A12: 저축성 | B12: 미래에셋생명 변액연금보험 무배당 (기본형, 미보증형) | D12: 일시납 | E12: =IY12/1200% -> 0.00246089 | F12: =IS12*$F$8 -> 0.008143344 | G12: =+M12/6 -> 0.001357224 | H12: =+G12 -> 0.001357224 | I12: =+H12 -> 0.001357224 | J12: =+I12 -> 0.001357224 | K12: =+J12 -> 0.001357224 | L12: =+K12 -> 0.001357224 | M12: =IT12*$F$8 -> 0.008143344 | N12: =+Z12/12 -> 0.00011931 | O12: =+N12 -> 0.00011931 | P12: =+O12 -> 0.00011931 | Q12: =+P12 -> 0.00011931 | R12: =+Q12 -> 0.00011931 | S12: =+R12 -> 0.00011931 | T12: =+S12 -> 0.00011931 | U12: =+T12 -> 0.00011931 | V12: =+U12 -> 0.00011931 | ... Y12: =+X12 -> 0.00011931 | Z12: =IU12*$F$8 -> 0.00143172 | AA12: =+AM12/12 -> 0 | AB12: =+AA12 -> 0 | AC12: =+AB12 -> 0 | AD12: =+AC12 -> 0 | AE12: =+AD12 -> 0 | AF12: =+AE12 -> 0 | AG12: =+AF12 -> 0 | AH12: =+AG12 -> 0 | AI12: =+AH12 -> 0 | ... AL12: =+AK12 -> 0 | AM12: =IV12*$F$8 -> 0 | AN12: =IW12*$F$8 -> 0 | AO12: =+DU12/83 -> 0.0002134748 | AP12: =+AO12 -> 0.0002134748 | AQ12: =+AP12 -> 0.0002134748 | AR12: =+AQ12 -> 0.0002134748 | AS12: =+AR12 -> 0.0002134748 | AT12: =+AS12 -> 0.0002134748 | AU12: =+AT12 -> 0.0002134748 | AV12: =+AU12 -> 0.0002134748 | AW12: =+AV12 -> 0.0002134748 | ... DS12: =+DR12 -> 0.0002134748 | DT12: =+IX12*$F$8 -> 0 | DU12: =+IY12*$F$8 -> 0.017718408 | DW12: =+ROUNDDOWN($DV12*E12,-1) -> 0 | DX12: =+ROUNDDOWN($DV12*F12,-1) -> 0 | DY12: =+ROUNDDOWN($DV12*G12,-1) -> 0 | DZ12: =+ROUNDDOWN($DV12*H12,-1) -> 0 | EA12: =+ROUNDDOWN($DV12*I12,-1) -> 0 | EB12: =+ROUNDDOWN($DV12*J12,-1) -> 0 | EC12: =+ROUNDDOWN($DV12*K12,-1) -> 0 | ED12: =+ROUNDDOWN($DV12*L12,-1) -> 0 | ... IL12: =+ROUNDDOWN($DV12*DT12,-1) -> 0 | IM12: =SUM(DX12,EE12,ER12,FE12,FF12,IL12) -> 0 | IS12: 0.01357224 | IT12: 0.01357224 | IU12: 0.0023862 | IV12: 0 | IW12: 0 | IX12: 0 | IY12: 0.02953068
A13: 저축성 | D13: 3년납이상 | E13: =IY13/1200% -> 0.0152872 | F13: =IS13*$F$8 -> 0.04071672 | G13: =+M13/6 -> 0.00678612 | H13: =+G13 -> 0.00678612 | I13: =+H13 -> 0.00678612 | J13: =+I13 -> 0.00678612 | K13: =+J13 -> 0.00678612 | L13: =+K13 -> 0.00678612 | M13: =IT13*$F$8 -> 0.04071672 | N13: =+Z13/12 -> 0.0023862 | O13: =+N13 -> 0.0023862 | P13: =+O13 -> 0.0023862 | Q13: =+P13 -> 0.0023862 | R13: =+Q13 -> 0.0023862 | S13: =+R13 -> 0.0023862 | T13: =+S13 -> 0.0023862 | U13: =+T13 -> 0.0023862 | V13: =+U13 -> 0.0023862 | ... Y13: =+X13 -> 0.0023862 | Z13: =IU13*$F$8 -> 0.0286344 | AA13: =+AM13/12 -> 0 | AB13: =+AA13 -> 0 | AC13: =+AB13 -> 0 | AD13: =+AC13 -> 0 | AE13: =+AD13 -> 0 | AF13: =+AE13 -> 0 | AG13: =+AF13 -> 0 | AH13: =+AG13 -> 0 | AI13: =+AH13 -> 0 | ... AL13: =+AK13 -> 0 | AM13: =IV13*$F$8 -> 0 | AN13: =IW13*$F$8 -> 0 | AO13: =+DU13/83 -> 0.0013261186 | AP13: =+AO13 -> 0.0013261186 | AQ13: =+AP13 -> 0.0013261186 | AR13: =+AQ13 -> 0.0013261186 | AS13: =+AR13 -> 0.0013261186 | AT13: =+AS13 -> 0.0013261186 | AU13: =+AT13 -> 0.0013261186 | AV13: =+AU13 -> 0.0013261186 | AW13: =+AV13 -> 0.0013261186 | ... DS13: =+DR13 -> 0.0013261186 | DT13: =+IX13*$F$8 -> 0 | DU13: =+IY13*$F$8 -> 0.11006784 | DW13: =+ROUNDDOWN($DV13*E13,-1) -> 0 | DX13: =+ROUNDDOWN($DV13*F13,-1) -> 0 | DY13: =+ROUNDDOWN($DV13*G13,-1) -> 0 | DZ13: =+ROUNDDOWN($DV13*H13,-1) -> 0 | EA13: =+ROUNDDOWN($DV13*I13,-1) -> 0 | EB13: =+ROUNDDOWN($DV13*J13,-1) -> 0 | EC13: =+ROUNDDOWN($DV13*K13,-1) -> 0 | ED13: =+ROUNDDOWN($DV13*L13,-1) -> 0 | ... IL13: =+ROUNDDOWN($DV13*DT13,-1) -> 0 | IM13: =SUM(DX13,EE13,ER13,FE13,FF13,IL13) -> 0 | IS13: 0.0678612 | IT13: 0.0678612 | IU13: 0.047724 | IV13: 0 | IW13: 0 | IX13: 0 | IY13: 0.1834464
A14: 저축성 | D14: 5년납이상 | E14: =IY14/1200% -> 0.19109 | F14: =IS14*$F$8 -> 0.508959 | G14: =+M14/6 -> 0.0848265 | H14: =+G14 -> 0.0848265 | I14: =+H14 -> 0.0848265 | J14: =+I14 -> 0.0848265 | K14: =+J14 -> 0.0848265 | L14: =+K14 -> 0.0848265 | M14: =IT14*$F$8 -> 0.508959 | N14: =+Z14/12 -> 0.0298275 | O14: =+N14 -> 0.0298275 | P14: =+O14 -> 0.0298275 | Q14: =+P14 -> 0.0298275 | R14: =+Q14 -> 0.0298275 | S14: =+R14 -> 0.0298275 | T14: =+S14 -> 0.0298275 | U14: =+T14 -> 0.0298275 | V14: =+U14 -> 0.0298275 | ... Y14: =+X14 -> 0.0298275 | Z14: =IU14*$F$8 -> 0.35793 | AA14: =+AM14/12 -> 0 | AB14: =+AA14 -> 0 | AC14: =+AB14 -> 0 | AD14: =+AC14 -> 0 | AE14: =+AD14 -> 0 | AF14: =+AE14 -> 0 | AG14: =+AF14 -> 0 | AH14: =+AG14 -> 0 | AI14: =+AH14 -> 0 | ... AL14: =+AK14 -> 0 | AM14: =IV14*$F$8 -> 0 | AN14: =IW14*$F$8 -> 0 | AO14: =+DU14/83 -> 0.016576482 | AP14: =+AO14 -> 0.016576482 | AQ14: =+AP14 -> 0.016576482 | AR14: =+AQ14 -> 0.016576482 | AS14: =+AR14 -> 0.016576482 | AT14: =+AS14 -> 0.016576482 | AU14: =+AT14 -> 0.016576482 | AV14: =+AU14 -> 0.016576482 | AW14: =+AV14 -> 0.016576482 | ... DS14: =+DR14 -> 0.016576482 | DT14: =+IX14*$F$8 -> 0 | DU14: =+IY14*$F$8 -> 1.375848 | DW14: =+ROUNDDOWN($DV14*E14,-1) -> 0 | DX14: =+ROUNDDOWN($DV14*F14,-1) -> 0 | DY14: =+ROUNDDOWN($DV14*G14,-1) -> 0 | DZ14: =+ROUNDDOWN($DV14*H14,-1) -> 0 | EA14: =+ROUNDDOWN($DV14*I14,-1) -> 0 | EB14: =+ROUNDDOWN($DV14*J14,-1) -> 0 | EC14: =+ROUNDDOWN($DV14*K14,-1) -> 0 | ED14: =+ROUNDDOWN($DV14*L14,-1) -> 0 | ... IL14: =+ROUNDDOWN($DV14*DT14,-1) -> 0 | IM14: =SUM(DX14,EE14,ER14,FE14,FF14,IL14) -> 0 | IS14: 0.848265 | IT14: 0.848265 | IU14: 0.59655 | IV14: 0 | IW14: 0 | IX14: 0 | IY14: 2.29308
A15: 저축성 | D15: 7년납이상 | E15: =IY15/1200% -> 0.3126504 | F15: =IS15*$F$8 -> 0.79397604 | G15: =+M15/6 -> 0.13232934 | H15: =+G15 -> 0.13232934 | I15: =+H15 -> 0.13232934 | J15: =+I15 -> 0.13232934 | K15: =+J15 -> 0.13232934 | L15: =+K15 -> 0.13232934 | M15: =IT15*$F$8 -> 0.79397604 | N15: =+Z15/12 -> 0.0508959 | O15: =+N15 -> 0.0508959 | P15: =+O15 -> 0.0508959 | Q15: =+P15 -> 0.0508959 | R15: =+Q15 -> 0.0508959 | S15: =+R15 -> 0.0508959 | T15: =+S15 -> 0.0508959 | U15: =+T15 -> 0.0508959 | V15: =+U15 -> 0.0508959 | ... Y15: =+X15 -> 0.0508959 | Z15: =IU15*$F$8 -> 0.6107508 | AA15: =+AM15/12 -> 0.004365 | AB15: =+AA15 -> 0.004365 | AC15: =+AB15 -> 0.004365 | AD15: =+AC15 -> 0.004365 | AE15: =+AD15 -> 0.004365 | AF15: =+AE15 -> 0.004365 | AG15: =+AF15 -> 0.004365 | AH15: =+AG15 -> 0.004365 | AI15: =+AH15 -> 0.004365 | ... AL15: =+AK15 -> 0.004365 | AM15: =IV15*$F$8 -> 0.05238 | AN15: =IW15*$F$8 -> 0 | AO15: =+DU15/83 -> 0.02712148 | AP15: =+AO15 -> 0.02712148 | AQ15: =+AP15 -> 0.02712148 | AR15: =+AQ15 -> 0.02712148 | AS15: =+AR15 -> 0.02712148 | AT15: =+AS15 -> 0.02712148 | AU15: =+AT15 -> 0.02712148 | AV15: =+AU15 -> 0.02712148 | AW15: =+AV15 -> 0.02712148 | ... DS15: =+DR15 -> 0.02712148 | DT15: =+IX15*$F$8 -> 0 | DU15: =+IY15*$F$8 -> 2.2510829 | DW15: =+ROUNDDOWN($DV15*E15,-1) -> 0 | DX15: =+ROUNDDOWN($DV15*F15,-1) -> 0 | DY15: =+ROUNDDOWN($DV15*G15,-1) -> 0 | DZ15: =+ROUNDDOWN($DV15*H15,-1) -> 0 | EA15: =+ROUNDDOWN($DV15*I15,-1) -> 0 | EB15: =+ROUNDDOWN($DV15*J15,-1) -> 0 | EC15: =+ROUNDDOWN($DV15*K15,-1) -> 0 | ED15: =+ROUNDDOWN($DV15*L15,-1) -> 0 | ... IL15: =+ROUNDDOWN($DV15*DT15,-1) -> 0 | IM15: =SUM(DX15,EE15,ER15,FE15,FF15,IL15) -> 0 | IS15: 1.3232934 | IT15: 1.3232934 | IU15: 1.017918 | IV15: 0.0873 | IW15: 0 | IX15: 0 | IY15: 3.7518048
A16: 저축성 | D16: 10년납이상 | E16: =IY16/1200% -> 0.449498 | F16: =IS16*$F$8 -> 1.1197098 | G16: =+M16/6 -> 0.1866183 | H16: =+G16 -> 0.1866183 | I16: =+H16 -> 0.1866183 | J16: =+I16 -> 0.1866183 | K16: =+J16 -> 0.1866183 | L16: =+K16 -> 0.1866183 | M16: =IT16*$F$8 -> 1.1197098 | N16: =+Z16/12 -> 0.0743505 | O16: =+N16 -> 0.0743505 | P16: =+O16 -> 0.0743505 | Q16: =+P16 -> 0.0743505 | R16: =+Q16 -> 0.0743505 | S16: =+R16 -> 0.0743505 | T16: =+S16 -> 0.0743505 | U16: =+T16 -> 0.0743505 | V16: =+U16 -> 0.0743505 | ... Y16: =+X16 -> 0.0743505 | Z16: =IU16*$F$8 -> 0.892206 | AA16: =+AM16/12 -> 0.00873 | AB16: =+AA16 -> 0.00873 | AC16: =+AB16 -> 0.00873 | AD16: =+AC16 -> 0.00873 | AE16: =+AD16 -> 0.00873 | AF16: =+AE16 -> 0.00873 | AG16: =+AF16 -> 0.00873 | AH16: =+AG16 -> 0.00873 | AI16: =+AH16 -> 0.00873 | ... AL16: =+AK16 -> 0.00873 | AM16: =IV16*$F$8 -> 0.10476 | AN16: =IW16*$F$8 -> 0 | AO16: =+DU16/83 -> 0.038992598 | AP16: =+AO16 -> 0.038992598 | AQ16: =+AP16 -> 0.038992598 | AR16: =+AQ16 -> 0.038992598 | AS16: =+AR16 -> 0.038992598 | AT16: =+AS16 -> 0.038992598 | AU16: =+AT16 -> 0.038992598 | AV16: =+AU16 -> 0.038992598 | AW16: =+AV16 -> 0.038992598 | ... DS16: =+DR16 -> 0.038992598 | DT16: =+IX16*$F$8 -> 0 | DU16: =+IY16*$F$8 -> 3.2363856 | DW16: =+ROUNDDOWN($DV16*E16,-1) -> 0 | DX16: =+ROUNDDOWN($DV16*F16,-1) -> 0 | DY16: =+ROUNDDOWN($DV16*G16,-1) -> 0 | DZ16: =+ROUNDDOWN($DV16*H16,-1) -> 0 | EA16: =+ROUNDDOWN($DV16*I16,-1) -> 0 | EB16: =+ROUNDDOWN($DV16*J16,-1) -> 0 | EC16: =+ROUNDDOWN($DV16*K16,-1) -> 0 | ED16: =+ROUNDDOWN($DV16*L16,-1) -> 0 | ... IL16: =+ROUNDDOWN($DV16*DT16,-1) -> 0 | IM16: =SUM(DX16,EE16,ER16,FE16,FF16,IL16) -> 0 | IS16: 1.866183 | IT16: 1.866183 | IU16: 1.48701 | IV16: 0.1746 | IW16: 0 | IX16: 0 | IY16: 5.393976
A17: 저축성 | B17: 미래에셋생명 변액연금보험 무배당 (연금액강화형, 미보증형) | D17: 일시납 | E17: =IY17/1200% -> 0.003691335 | F17: =IS17*$F$8 -> 0.012215016 | G17: =+M17/6 -> 0.002035836 | H17: =+G17 -> 0.002035836 | I17: =+H17 -> 0.002035836 | J17: =+I17 -> 0.002035836 | K17: =+J17 -> 0.002035836 | L17: =+K17 -> 0.002035836 | M17: =IT17*$F$8 -> 0.012215016 | N17: =+Z17/12 -> 0.000178965 | O17: =+N17 -> 0.000178965 | P17: =+O17 -> 0.000178965 | Q17: =+P17 -> 0.000178965 | R17: =+Q17 -> 0.000178965 | S17: =+R17 -> 0.000178965 | T17: =+S17 -> 0.000178965 | U17: =+T17 -> 0.000178965 | V17: =+U17 -> 0.000178965 | ... Y17: =+X17 -> 0.000178965 | Z17: =IU17*$F$8 -> 0.00214758 | AA17: =+AM17/12 -> 0 | AB17: =+AA17 -> 0 | AC17: =+AB17 -> 0 | AD17: =+AC17 -> 0 | AE17: =+AD17 -> 0 | AF17: =+AE17 -> 0 | AG17: =+AF17 -> 0 | AH17: =+AG17 -> 0 | AI17: =+AH17 -> 0 | ... AL17: =+AK17 -> 0 | AM17: =IV17*$F$8 -> 0 | AN17: =IW17*$F$8 -> 0 | AO17: =+DU17/83 -> 0.00032021219 | AP17: =+AO17 -> 0.00032021219 | AQ17: =+AP17 -> 0.00032021219 | AR17: =+AQ17 -> 0.00032021219 | AS17: =+AR17 -> 0.00032021219 | AT17: =+AS17 -> 0.00032021219 | AU17: =+AT17 -> 0.00032021219 | AV17: =+AU17 -> 0.00032021219 | AW17: =+AV17 -> 0.00032021219 | ... DS17: =+DR17 -> 0.00032021219 | DT17: =+IX17*$F$8 -> 0 | DU17: =+IY17*$F$8 -> 0.026577612 | DW17: =+ROUNDDOWN($DV17*E17,-1) -> 0 | DX17: =+ROUNDDOWN($DV17*F17,-1) -> 0 | DY17: =+ROUNDDOWN($DV17*G17,-1) -> 0 | DZ17: =+ROUNDDOWN($DV17*H17,-1) -> 0 | EA17: =+ROUNDDOWN($DV17*I17,-1) -> 0 | EB17: =+ROUNDDOWN($DV17*J17,-1) -> 0 | EC17: =+ROUNDDOWN($DV17*K17,-1) -> 0 | ED17: =+ROUNDDOWN($DV17*L17,-1) -> 0 | ... IL17: =+ROUNDDOWN($DV17*DT17,-1) -> 0 | IM17: =SUM(DX17,EE17,ER17,FE17,FF17,IL17) -> 0 | IS17: 0.02035836 | IT17: 0.02035836 | IU17: 0.0035793 | IV17: 0 | IW17: 0 | IX17: 0 | IY17: 0.04429602
A18: 저축성 | D18: 3년납이상 | E18: =IY18/1200% -> 0.19109 | F18: =IS18*$F$8 -> 0.508959 | G18: =+M18/6 -> 0.0848265 | H18: =+G18 -> 0.0848265 | I18: =+H18 -> 0.0848265 | J18: =+I18 -> 0.0848265 | K18: =+J18 -> 0.0848265 | L18: =+K18 -> 0.0848265 | M18: =IT18*$F$8 -> 0.508959 | N18: =+Z18/12 -> 0.0298275 | O18: =+N18 -> 0.0298275 | P18: =+O18 -> 0.0298275 | Q18: =+P18 -> 0.0298275 | R18: =+Q18 -> 0.0298275 | S18: =+R18 -> 0.0298275 | T18: =+S18 -> 0.0298275 | U18: =+T18 -> 0.0298275 | V18: =+U18 -> 0.0298275 | ... Y18: =+X18 -> 0.0298275 | Z18: =IU18*$F$8 -> 0.35793 | AA18: =+AM18/12 -> 0 | AB18: =+AA18 -> 0 | AC18: =+AB18 -> 0 | AD18: =+AC18 -> 0 | AE18: =+AD18 -> 0 | AF18: =+AE18 -> 0 | AG18: =+AF18 -> 0 | AH18: =+AG18 -> 0 | AI18: =+AH18 -> 0 | ... AL18: =+AK18 -> 0 | AM18: =IV18*$F$8 -> 0 | AN18: =IW18*$F$8 -> 0 | AO18: =+DU18/83 -> 0.016576482 | AP18: =+AO18 -> 0.016576482 | AQ18: =+AP18 -> 0.016576482 | AR18: =+AQ18 -> 0.016576482 | AS18: =+AR18 -> 0.016576482 | AT18: =+AS18 -> 0.016576482 | AU18: =+AT18 -> 0.016576482 | AV18: =+AU18 -> 0.016576482 | AW18: =+AV18 -> 0.016576482 | ... DS18: =+DR18 -> 0.016576482 | DT18: =+IX18*$F$8 -> 0 | DU18: =+IY18*$F$8 -> 1.375848 | DW18: =+ROUNDDOWN($DV18*E18,-1) -> 0 | DX18: =+ROUNDDOWN($DV18*F18,-1) -> 0 | DY18: =+ROUNDDOWN($DV18*G18,-1) -> 0 | DZ18: =+ROUNDDOWN($DV18*H18,-1) -> 0 | EA18: =+ROUNDDOWN($DV18*I18,-1) -> 0 | EB18: =+ROUNDDOWN($DV18*J18,-1) -> 0 | EC18: =+ROUNDDOWN($DV18*K18,-1) -> 0 | ED18: =+ROUNDDOWN($DV18*L18,-1) -> 0 | ... IL18: =+ROUNDDOWN($DV18*DT18,-1) -> 0 | IM18: =SUM(DX18,EE18,ER18,FE18,FF18,IL18) -> 0 | IS18: 0.848265 | IT18: 0.848265 | IU18: 0.59655 | IV18: 0 | IW18: 0 | IX18: 0 | IY18: 2.29308
A19: 저축성 | D19: 5년납이상 | E19: =IY19/1200% -> 0.373062 | F19: =IS19*$F$8 -> 0.9161262 | G19: =+M19/6 -> 0.1526877 | H19: =+G19 -> 0.1526877 | I19: =+H19 -> 0.1526877 | J19: =+I19 -> 0.1526877 | K19: =+J19 -> 0.1526877 | L19: =+K19 -> 0.1526877 | M19: =IT19*$F$8 -> 0.9161262 | N19: =+Z19/12 -> 0.0624195 | O19: =+N19 -> 0.0624195 | P19: =+O19 -> 0.0624195 | Q19: =+P19 -> 0.0624195 | R19: =+Q19 -> 0.0624195 | S19: =+R19 -> 0.0624195 | T19: =+S19 -> 0.0624195 | U19: =+T19 -> 0.0624195 | V19: =+U19 -> 0.0624195 | ... Y19: =+X19 -> 0.0624195 | Z19: =IU19*$F$8 -> 0.749034 | AA19: =+AM19/12 -> 0.00873 | AB19: =+AA19 -> 0.00873 | AC19: =+AB19 -> 0.00873 | AD19: =+AC19 -> 0.00873 | AE19: =+AD19 -> 0.00873 | AF19: =+AE19 -> 0.00873 | AG19: =+AF19 -> 0.00873 | AH19: =+AG19 -> 0.00873 | AI19: =+AH19 -> 0.00873 | ... AL19: =+AK19 -> 0.00873 | AM19: =IV19*$F$8 -> 0.10476 | AN19: =IW19*$F$8 -> 0 | AO19: =+DU19/83 -> 0.032362005 | AP19: =+AO19 -> 0.032362005 | AQ19: =+AP19 -> 0.032362005 | AR19: =+AQ19 -> 0.032362005 | AS19: =+AR19 -> 0.032362005 | AT19: =+AS19 -> 0.032362005 | AU19: =+AT19 -> 0.032362005 | AV19: =+AU19 -> 0.032362005 | AW19: =+AV19 -> 0.032362005 | ... DS19: =+DR19 -> 0.032362005 | DT19: =+IX19*$F$8 -> 0 | DU19: =+IY19*$F$8 -> 2.6860464 | DW19: =+ROUNDDOWN($DV19*E19,-1) -> 0 | DX19: =+ROUNDDOWN($DV19*F19,-1) -> 0 | DY19: =+ROUNDDOWN($DV19*G19,-1) -> 0 | DZ19: =+ROUNDDOWN($DV19*H19,-1) -> 0 | EA19: =+ROUNDDOWN($DV19*I19,-1) -> 0 | EB19: =+ROUNDDOWN($DV19*J19,-1) -> 0 | EC19: =+ROUNDDOWN($DV19*K19,-1) -> 0 | ED19: =+ROUNDDOWN($DV19*L19,-1) -> 0 | ... IL19: =+ROUNDDOWN($DV19*DT19,-1) -> 0 | IM19: =SUM(DX19,EE19,ER19,FE19,FF19,IL19) -> 0 | IS19: 1.526877 | IT19: 1.526877 | IU19: 1.24839 | IV19: 0.1746 | IW19: 0 | IX19: 0 | IY19: 4.476744
